Workbook

Sheet Guide
A1: EASM Mission Tracker — Guide
A2: Cyber Risk Intelligence (2LoD) — one workbook for meetings, communications, tasks, goals, developments and EASM findings, producing the weekly status report automatically.
A4: WEEKLY ROUTINE (≈15 min before the meeting)
A5: 1 · During the week | B5: Log as things happen: Meetings, Emails, Developments, EASM Findings. On Tasks keep Status, % Complete, Last Update Date and Latest Update Note current.
A6: 2 · Findings | B6: When severity, status, exploitation, ownership or RAF view changes, set 'Last Material Change Date' and describe the change. New/changed findings flow to section 5.
A7: 3 · Goals | B7: Copy 'Current Value' into 'Value Last Week', then enter the new Current Value and Last Updated date.
A8: 4 · Plan & dependencies | B8: On Tasks set 'Planned for Next Week? = Yes' and fill 'Dependency On' / 'Needed By' for anything waiting on others. On Developments set 'Decision / Escalation Required? = Yes' with the ask, decision owner and date.
A9: 5 · Weekly Status Log | B9: Add a row with the meeting date. The Weekly Report switches to that week automatically.
A10: 6 · Weekly Report | B10: Review sections 1–8. Compare the indicator-based status with your call; resolve any CHALLENGE flag. Then write your RAG, one-sentence 'Why' and commentary in the Weekly Status Log row.
A11: 7 · Present | B11: Print or export the Weekly Report tab to PDF (landscape, fits to width). After the meeting, record decisions and actions in the same log row and create the tasks.
A12: WEEKLY REPORT SECTIONS
A13: 1 · Overall timeline | B13: Mission dates, % elapsed, current phase and a text Gantt of the phase plan (Mission Charter) with a today marker.
A14: 2 · Overall status | B14: Your RAG and one-sentence rationale, previous week and trend, indicator-based RAG from 13 drivers with editable thresholds, and a 2LoD consistency check.
A15: 3 · Progress since last week | B15: Tasks completed; tasks moved forward; KPI week-on-week movement; developments and decisions; meetings held.
A16: 4 · Current work | B16: All tasks In Progress with % complete, due flag and latest note.
A17: 5 · Findings | B17: Only findings discovered or materially changed in the period, with remediation owner, status, target date, SLA and RAF; plus remediation targets due by end of next week.
A18: 6 · Blockers / dependencies | B18: Blocked tasks and tasks waiting on a named person/team; overdue or outstanding responses from 1LoD and third parties.
A19: 7 · Plan for next week | B19: Open tasks flagged for next week, due by end of next week (incl. overdue) or starting next week.
A20: 8 · Escalation / decision needed | B20: Open decisions and escalations (Developments) and open findings in RAF breach.
A21: Reporting period | B21: Defaults to the day after the previous log entry up to the meeting date (or the last 7 days). Both dates can be overridden in the white cells at the top of the Weekly Report.
A22: LEGEND
A23: White cell | B23: Your input. Type, paste or pick from the dropdown.
A24: Grey cell | B24: Automatic formula (IDs, flags, days open, SLA, progress, report content). Do not overwrite.
A25: Light-green cell | B25: Key assumption (Severity → SLA table on Lists). Review and align to the bank's standard.
A26: Red / amber / green | B26: Conditional formatting: overdue, SLA breach, RAF breach, RAG, status and severity.
A27: Example rows | B27: Row 5 of every log tab is an illustrative example (italic), dated in the current week so the Weekly Report shows how it works. Overwrite or delete before go-live.
A28: Hidden helper columns | B28: Columns headed 'WR helper' (grey, grouped and collapsed at the right of each log) feed the Weekly Report. Do not delete them; expand with the [+] button if needed.
A29: TABS
A30: Weekly Report | B30: Auto-built weekly status pack (sections 1–8).
A31: Weekly Status Log (WSR-) | B31: One row per weekly meeting: RAG, why, commentary per section, decisions and actions; previous RAG and trend calculate automatically.
A32: Dashboard | B32: Cumulative mission KPIs and charts, including latest reported vs indicator-based RAG.
A33: Mission Charter | B33: Scope, objectives, drivers, governance and the 6-phase plan driving the timeline.
A34: Goals & KPIs (GOL-) | B34: Objectives and key results with last-week vs current value and progress to target.
A35: Meetings (MTG-) / Emails (EML-) | B35: Meetings with decisions, 2LoD challenge and follow-ups; material emails with response SLAs.
A36: Tasks (TSK-) | B36: Actions with owner, priority, progress notes, dependencies and next-week flag.
A37: Developments (DEV-) | B37: Milestones, decisions, scope changes, escalations and risk acceptances, including decision asks and outcomes.
A38: EASM Findings (FND-) | B38: Exposure register: technical vector → operational vulnerability → systemic/concentration risk → financial/regulatory impact → RAF, with SLA and weekly change tracking.
A39: Stakeholders (STK-) / Lists | B39: RACI, stance and contact cadence; dropdown values and the SLA table.
A40: Cross-referencing | B40: Link records by ID (e.g. a task's Source Ref = MTG-004). Separate multiple IDs with ';'.

Sheet Weekly Report
A1: EASM Mission — Weekly Status Report
A2: ="Reporting period: "&TEXT(F4,"dd-mmm-yyyy")&" to "&TEXT(F5,"dd-mmm-yyyy")&" | Meeting date: "&TEXT(C5,"dd-mmm-yyyy")&" | Generated: "&TEXT(TODAY(),"dd-mmm-yyyy") -> Reporting period: 14-Oct-2026 to 20-Oct-2026 | Meeting date: 20-Oct-2026 | Generated: 20-Oct-2026
B4: Meeting date — override (optional) | E4: Period start | F4: =IF(C7<>"",C7,IF(C6="",C5-6,IF(C5-C6<=14,C6+1,C5-6))) -> 46309 | H4: How it works: add this week's row in 'Weekly Status Log' (date + RAG + one sentence). Everything below fills automatically from the logs for the period shown.
B5: Meeting date used | C5: =IF(C4<>"",C4,IF(COUNT('Weekly Status Log'!$B$5:$B$108)=0,TODAY(),MAX('Weekly Status Log'!$B$5:$B$108))) -> 46315 | E5: Period end | F5: =C5 -> 46315
B6: Previous meeting (from Weekly Status Log) | C6: =IF(_xlfn.MAXIFS('Weekly Status Log'!$B$5:$B$108,'Weekly Status Log'!$B$5:$B$108,"<"&C5)=0,"",_xlfn.MAXIFS('Weekly Status Log'!$B$5:$B$108,'Weekly Status Log'!$B$5:$B$108,"<"&C5)) | E6: Next week from | F6: =C5+1 -> 46316
B7: Period start — override (optional) | E7: Next week to | F7: =C5+7 -> 46322
B8: Weekly Status Log entry | C8: =IF(J8="","Not found — add a row","WSR-"&TEXT(J8,"000")) -> WSR-001 | J8: =IFERROR(MATCH(C5,'Weekly Status Log'!$B$5:$B$108,0),"") -> 1
A10: 1 · OVERALL TIMELINE
B11: Mission start | C11: ='Mission Charter'!B9 -> 46296 | E11: Planned end | G11: ='Mission Charter'!B10 -> 46477
B12: Days elapsed | C12: ='Mission Charter'!B11 -> 19 | E12: Days remaining | G12: ='Mission Charter'!B12 -> 162
B13: % of timeline elapsed | C13: ='Mission Charter'!B13 -> 0.10497238 | E13: Phases completed | G13: =COUNTIF('Mission Charter'!$F$28:$F$33,"Completed")&" of 6" -> 1 of 6
B14: Current phase | C14: =IFERROR(INDEX('Mission Charter'!$A$28:$A$33,MATCH("In Progress",'Mission Charter'!$F$28:$F$33,0)),IF(COUNTIF('Mission Charter'!$F$28:$F$33,"Completed")=6,"All phases complete","No phase In Progress")) -> 2. Discovery & Attribution | E14: Current phase ends | G14: =IFERROR(INDEX('Mission Charter'!$D$28:$D$33,MATCH("In Progress",'Mission Charter'!$F$28:$F$33,0)),"") -> 46340
A16: Phase | B16: Phase name | C16: Status | D16: Planned start | E16: Planned end | F16: Actual end | G16: Variance (d) | H16: Timeline (█ planned · ▼ today)
B17: =IF('Mission Charter'!$B$9="","","Scale: "&TEXT('Mission Charter'!$B$9,"dd-mmm-yy")&" → "&TEXT('Mission Charter'!$B$10,"dd-mmm-yy")) -> Scale: 01-Oct-26 → 31-Mar-27 | H17: =IF(OR('Mission Charter'!$B$9="",'Mission Charter'!$B$10="",'Mission Charter'!$B$10<='Mission Charter'!$B$9),"",REPT(" ",ROUND(MIN(1,MAX(0,(TODAY()-'Mission Charter'!$B$9)/('Mission Charter'!$B$10-'Mission Charter'!$B$9)))*40,0))&"▼ "&TEXT(TODAY(),"dd-mmm")) -> ▼ 20-Oct
A18: P1 | B18: ='Mission Charter'!A28 -> 1. Scoping & Baseline | C18: ='Mission Charter'!F28 -> Completed | D18: =IF('Mission Charter'!C28="","",'Mission Charter'!C28) -> 46296 | E18: =IF('Mission Charter'!D28="","",'Mission Charter'!D28) -> 46312 | F18: =IF('Mission Charter'!E28="","",'Mission Charter'!E28) -> 46311 | G18: ='Mission Charter'!G28 -> -1 | H18: =IF(OR('Mission Charter'!C28="",'Mission Charter'!D28="",'Mission Charter'!$B$9="",'Mission Charter'!$B$10="",'Mission Charter'!$B$10<='Mission Charter'!$B$9),"",REPT(" ",MAX(0,ROUND(('Mission Charter'!C28-'Mission Charter'!$B$9)/('Mission Charter'!$B$10-'Mission Charter'!$B$9)*40,0)))&REPT("█",MAX(1,ROUND((MIN('Mission Charter'!D28,'Mission Charter'!$B$10)-MAX('Mission Charter'!C28,'Mission Charter'!$B$9))/('Mission Charter'!$B$10-'Mission Charter'!$B$9)*40,0)))) -> ████
A19: P2 | B19: ='Mission Charter'!A29 -> 2. Discovery & Attribution | C19: ='Mission Charter'!F29 -> In Progress | D19: =IF('Mission Charter'!C29="","",'Mission Charter'!C29) -> 46307 | E19: =IF('Mission Charter'!D29="","",'Mission Charter'!D29) -> 46340 | F19: =IF('Mission Charter'!E29="","",'Mission Charter'!E29) | G19: ='Mission Charter'!G29 | H19: =IF(OR('Mission Charter'!C29="",'Mission Charter'!D29="",'Mission Charter'!$B$9="",'Mission Charter'!$B$10="",'Mission Charter'!$B$10<='Mission Charter'!$B$9),"",REPT(" ",MAX(0,ROUND(('Mission Charter'!C29-'Mission Charter'!$B$9)/('Mission Charter'!$B$10-'Mission Charter'!$B$9)*40,0)))&REPT("█",MAX(1,ROUND((MIN('Mission Charter'!D29,'Mission Charter'!$B$10)-MAX('Mission Charter'!C29,'Mission Charter'!$B$9))/('Mission Charter'!$B$10-'Mission Charter'!$B$9)*40,0)))) -> ███████
A20: P3 | B20: ='Mission Charter'!A30 -> 3. Exposure Assessment | C20: ='Mission Charter'!F30 -> Not Started | D20: =IF('Mission Charter'!C30="","",'Mission Charter'!C30) -> 46328 | E20: =IF('Mission Charter'!D30="","",'Mission Charter'!D30) -> 46375 | F20: =IF('Mission Charter'!E30="","",'Mission Charter'!E30) | G20: ='Mission Charter'!G30 | H20: =IF(OR('Mission Charter'!C30="",'Mission Charter'!D30="",'Mission Charter'!$B$9="",'Mission Charter'!$B$10="",'Mission Charter'!$B$10<='Mission Charter'!$B$9),"",REPT(" ",MAX(0,ROUND(('Mission Charter'!C30-'Mission Charter'!$B$9)/('Mission Charter'!$B$10-'Mission Charter'!$B$9)*40,0)))&REPT("█",MAX(1,ROUND((MIN('Mission Charter'!D30,'Mission Charter'!$B$10)-MAX('Mission Charter'!C30,'Mission Charter'!$B$9))/('Mission Charter'!$B$10-'Mission Charter'!$B$9)*40,0)))) -> ██████████
A21: P4 | B21: ='Mission Charter'!A31 -> 4. Risk Translation & 1LoD Challenge | C21: ='Mission Charter'!F31 -> Not Started | D21: =IF('Mission Charter'!C31="","",'Mission Charter'!C31) -> 46356 | E21: =IF('Mission Charter'!D31="","",'Mission Charter'!D31) -> 46416 | F21: =IF('Mission Charter'!E31="","",'Mission Charter'!E31) | G21: ='Mission Charter'!G31 | H21: =IF(OR('Mission Charter'!C31="",'Mission Charter'!D31="",'Mission Charter'!$B$9="",'Mission Charter'!$B$10="",'Mission Charter'!$B$10<='Mission Charter'!$B$9),"",REPT(" ",MAX(0,ROUND(('Mission Charter'!C31-'Mission Charter'!$B$9)/('Mission Charter'!$B$10-'Mission Charter'!$B$9)*40,0)))&REPT("█",MAX(1,ROUND((MIN('Mission Charter'!D31,'Mission Charter'!$B$10)-MAX('Mission Charter'!C31,'Mission Charter'!$B$9))/('Mission Charter'!$B$10-'Mission Charter'!$B$9)*40,0)))) -> █████████████
A22: P5 | B22: ='Mission Charter'!A32 -> 5. Remediation Oversight | C22: ='Mission Charter'!F32 -> Not Started | D22: =IF('Mission Charter'!C32="","",'Mission Charter'!C32) -> 46391 | E22: =IF('Mission Charter'!D32="","",'Mission Charter'!D32) -> 46458 | F22: =IF('Mission Charter'!E32="","",'Mission Charter'!E32) | G22: ='Mission Charter'!G32 | H22: =IF(OR('Mission Charter'!C32="",'Mission Charter'!D32="",'Mission Charter'!$B$9="",'Mission Charter'!$B$10="",'Mission Charter'!$B$10<='Mission Charter'!$B$9),"",REPT(" ",MAX(0,ROUND(('Mission Charter'!C32-'Mission Charter'!$B$9)/('Mission Charter'!$B$10-'Mission Charter'!$B$9)*40,0)))&REPT("█",MAX(1,ROUND((MIN('Mission Charter'!D32,'Mission Charter'!$B$10)-MAX('Mission Charter'!C32,'Mission Charter'!$B$9))/('Mission Charter'!$B$10-'Mission Charter'!$B$9)*40,0)))) -> ███████████████
A23: P6 | B23: ='Mission Charter'!A33 -> 6. Reporting & Closure | C23: ='Mission Charter'!F33 -> Not Started | D23: =IF('Mission Charter'!C33="","",'Mission Charter'!C33) -> 46447 | E23: =IF('Mission Charter'!D33="","",'Mission Charter'!D33) -> 46477 | F23: =IF('Mission Charter'!E33="","",'Mission Charter'!E33) | G23: ='Mission Charter'!G33 | H23: =IF(OR('Mission Charter'!C33="",'Mission Charter'!D33="",'Mission Charter'!$B$9="",'Mission Charter'!$B$10="",'Mission Charter'!$B$10<='Mission Charter'!$B$9),"",REPT(" ",MAX(0,ROUND(('Mission Charter'!C33-'Mission Charter'!$B$9)/('Mission Charter'!$B$10-'Mission Charter'!$B$9)*40,0)))&REPT("█",MAX(1,ROUND((MIN('Mission Charter'!D33,'Mission Charter'!$B$10)-MAX('Mission Charter'!C33,'Mission Charter'!$B$9))/('Mission Charter'!$B$10-'Mission Charter'!$B$9)*40,0)))) -> ███████
A25: 2 · OVERALL STATUS
B26: Reported status (your call) | C26: =IF($J$8="","",IF(INDEX('Weekly Status Log'!$C$5:$C$108,$J$8)="","Not set",INDEX('Weekly Status Log'!$C$5:$C$108,$J$8))) -> Amber | D26: =IF($J$8="","Add this week's row in the Weekly Status Log",IF(INDEX('Weekly Status Log'!$D$5:$D$108,$J$8)="","(one-sentence rationale not entered)",INDEX('Weekly Status Log'!$D$5:$D$108,$J$8))) -> Discovery is on plan, but attribution is constrained by an outstanding 1LoD CMDB extract and an open sponsor decision on scope extension.
B27: Previous week / trend | C27: =IF($J$8="","",IF(INDEX('Weekly Status Log'!$M$5:$M$108,$J$8)="","—",INDEX('Weekly Status Log'!$M$5:$M$108,$J$8))) -> — | D27: =IF($J$8="","",IF(INDEX('Weekly Status Log'!$N$5:$N$108,$J$8)="","",INDEX('Weekly Status Log'!$N$5:$N$108,$J$8)))
B28: Indicator-based status (suggested) | C28: =IF(COUNTIF(F32:F44,"Red")>0,"Red",IF(COUNTIF(F32:F44,"Amber")>0,"Amber","Green")) -> Amber | D28: =COUNTIF(F32:F44,"Red")&" Red and "&COUNTIF(F32:F44,"Amber")&" Amber driver(s) triggered — see table below" -> 0 Red and 1 Amber driver(s) triggered — see table below
B29: 2LoD consistency check | D29: =IF(OR(C26="",C26="Not set"),"Enter your RAG call in the Weekly Status Log",IF(MATCH(C26,{"Red","Amber","Green"},0)>MATCH(C28,{"Red","Amber","Green"},0),"CHALLENGE: reported status is more favourable than the indicators — evidence the judgement before the meeting",IF(MATCH(C26,{"Red","Amber","Green"},0)<MATCH(C28,{"Red","Amber","Green"},0),"Reported status is more conservative than the indicators — state the forward-looking concern","Consistent with indicators"))) -> Consistent with indicators
B31: Status driver (from logs) | C31: Count | D31: Drives | E31: Threshold (≥) | F31: Triggered | G31: Source tab
B32: Open Critical/High findings breaching remediation SLA | C32: =COUNTIFS('EASM Findings'!$AA$5:$AA$304,"SLA BREACH",'EASM Findings'!$L$5:$L$304,"Critical")+COUNTIFS('EASM Findings'!$AA$5:$AA$304,"SLA BREACH",'EASM Findings'!$L$5:$L$304,"High") -> 0 | D32: Red | E32: 1 | F32: =IF(C32>=E32,D32,"—") -> — | G32: EASM Findings
B33: RAF appetite breaches (open findings + developments) | C33: =COUNTIFS('EASM Findings'!$E$5:$E$304,"<>",'EASM Findings'!$U$5:$U$304,"<>Remediated",'EASM Findings'!$U$5:$U$304,"<>False Positive",'EASM Findings'!$U$5:$U$304,"<>Risk Accepted",'EASM Findings'!$Q$5:$Q$304,"Breach - Appetite")+COUNTIF(Developments!$L$5:$L$304,"Breach - Appetite") -> 0 | D33: Red | E33: 1 | F33: =IF(C33>=E33,D33,"—") -> — | G33: Findings / Developments
B34: Goals Off Track | C34: =COUNTIF('Goals & KPIs'!$P$5:$P$304,"Off Track") -> 0 | D34: Red | E34: 1 | F34: =IF(C34>=E34,D34,"—") -> — | G34: Goals & KPIs
B35: Overdue Critical-priority tasks | C35: =COUNTIFS(Tasks!$X$5:$X$304,"OVERDUE",Tasks!$J$5:$J$304,"Critical") -> 0 | D35: Red | E35: 1 | F35: =IF(C35>=E35,D35,"—") -> — | G35: Tasks
B36: Mission past planned end with phases open | C36: =IF(AND('Mission Charter'!$B$10<>"",TODAY()>'Mission Charter'!$B$10,COUNTIF('Mission Charter'!$F$28:$F$33,"Completed")<6),1,0) -> 0 | D36: Red | E36: 1 | F36: =IF(C36>=E36,D36,"—") -> — | G36: Mission Charter
B37: Overdue tasks (all priorities) | C37: =COUNTIF(Tasks!$X$5:$X$304,"OVERDUE") -> 0 | D37: Amber | E37: 1 | F37: =IF(C37>=E37,D37,"—") -> — | G37: Tasks
B38: Blocked tasks | C38: =COUNTIF(Tasks!$K$5:$K$304,"Blocked") -> 0 | D38: Amber | E38: 1 | F38: =IF(C38>=E38,D38,"—") -> — | G38: Tasks
B39: Goals At Risk | C39: =COUNTIF('Goals & KPIs'!$P$5:$P$304,"At Risk") -> 0 | D39: Amber | E39: 1 | F39: =IF(C39>=E39,D39,"—") -> — | G39: Goals & KPIs
B40: Overdue responses from 1LoD / third parties | C40: =COUNTIF(Emails!$R$5:$R$304,"OVERDUE") -> 0 | D40: Amber | E40: 1 | F40: =IF(C40>=E40,D40,"—") -> — | G40: Emails
B41: Open decisions / escalations awaiting outcome | C41: =COUNT(Developments!$X$5:$X$304) -> 1 | D41: Amber | E41: 1 | F41: =IF(C41>=E41,D41,"—") -> Amber | G41: Developments
B42: Open Medium/Low findings breaching SLA | C42: =COUNTIF('EASM Findings'!$AA$5:$AA$304,"SLA BREACH")-COUNTIFS('EASM Findings'!$AA$5:$AA$304,"SLA BREACH",'EASM Findings'!$L$5:$L$304,"Critical")-COUNTIFS('EASM Findings'!$AA$5:$AA$304,"SLA BREACH",'EASM Findings'!$L$5:$L$304,"High") -> 0 | D42: Amber | E42: 1 | F42: =IF(C42>=E42,D42,"—") -> — | G42: EASM Findings
B43: RAF tolerance breaches (open findings + developments) | C43: =COUNTIFS('EASM Findings'!$E$5:$E$304,"<>",'EASM Findings'!$U$5:$U$304,"<>Remediated",'EASM Findings'!$U$5:$U$304,"<>False Positive",'EASM Findings'!$U$5:$U$304,"<>Risk Accepted",'EASM Findings'!$Q$5:$Q$304,"Breach - Tolerance")+COUNTIF(Developments!$L$5:$L$304,"Breach - Tolerance") -> 0 | D43: Amber | E43: 1 | F43: =IF(C43>=E43,D43,"—") -> — | G43: Findings / Developments
B44: Phases delayed or finished late | C44: =COUNTIF('Mission Charter'!$F$28:$F$33,"Delayed")+COUNTIF('Mission Charter'!$G$28:$G$33,">0") -> 0 | D44: Amber | E44: 1 | F44: =IF(C44>=E44,D44,"—") -> — | G44: Mission Charter
B45: Thresholds (white cells) are editable — calibrate to the mission's risk tolerance. Any Red driver ⇒ Red; otherwise any Amber driver ⇒ Amber; otherwise Green.
...

Sheet Weekly Status Log
A1: Weekly Status Log
A2: One row per weekly meeting: your RAG call, one-sentence rationale and commentary. The Weekly Report picks up the latest row automatically.
A3: White cells = your input | Grey cells = automatic (do not overwrite) | Row 5 is an illustrative example (italic) — overwrite or delete it.
A4: Week ID | B4: Meeting Date | C4: Overall Status (RAG) | D4: Why — one sentence | E4: Progress Highlights (commentary) | F4: Current Work (commentary) | G4: Findings Commentary | H4: Blockers / Dependencies (commentary) | I4: Plan for Next Week (commentary) | J4: Escalation / Decision Needed (commentary) | K4: Decisions Taken at Meeting | L4: Actions Agreed (Task IDs) | M4: Previous RAG | N4: RAG Trend | O4: Notes
A5: WSR-001 | B5: 46315 | C5: Amber | D5: Discovery is on plan, but attribution is constrained by an outstanding 1LoD CMDB extract and an open sponsor decision on scope extension. | E5: Phase 1 closed; Entity A reconciled (+4pp attribution); critical legacy VPN exposure identified at acquired Entity B. | F5: CMDB reconciliation for Entities B–C; validation of FND-001 with Network Security. | G5: FND-001 (Critical) under validation; single-vendor remote-access concentration across acquired entities. | H5: Entity C CMDB extract (Network Security, needed 23-Oct). | I5: Complete reconciliation; confirm FND-001 exploitability and remediation owner; prepare Phase 3 test plan. | J5: Sponsor approval of scope extension and +3 weeks on Phase 2 (DEV-001, by 30-Oct). | M5: =IF(B5="","",IF(_xlfn.MAXIFS($B$5:$B$108,$B$5:$B$108,"<"&B5)=0,"",IF(INDEX($C$5:$C$108,MATCH(_xlfn.MAXIFS($B$5:$B$108,$B$5:$B$108,"<"&B5),$B$5:$B$108,0))="","",INDEX($C$5:$C$108,MATCH(_xlfn.MAXIFS($B$5:$B$108,$B$5:$B$108,"<"&B5),$B$5:$B$108,0))))) | N5: =IF(OR(C5="",M5=""),"",IF(MATCH(C5,{"Red","Amber","Green"},0)>MATCH(M5,{"Red","Amber","Green"},0),"▲ Improving",IF(MATCH(C5,{"Red","Amber","Green"},0)<MATCH(M5,{"Red","Amber","Green"},0),"▼ Deteriorating","► Stable")))
A6: WSR-002 | M6: =IF(B6="","",IF(_xlfn.MAXIFS($B$5:$B$108,$B$5:$B$108,"<"&B6)=0,"",IF(INDEX($C$5:$C$108,MATCH(_xlfn.MAXIFS($B$5:$B$108,$B$5:$B$108,"<"&B6),$B$5:$B$108,0))="","",INDEX($C$5:$C$108,MATCH(_xlfn.MAXIFS($B$5:$B$108,$B$5:$B$108,"<"&B6),$B$5:$B$108,0))))) | N6: =IF(OR(C6="",M6=""),"",IF(MATCH(C6,{"Red","Amber","Green"},0)>MATCH(M6,{"Red","Amber","Green"},0),"▲ Improving",IF(MATCH(C6,{"Red","Amber","Green"},0)<MATCH(M6,{"Red","Amber","Green"},0),"▼ Deteriorating","► Stable")))
A7: WSR-003 | M7: =IF(B7="","",IF(_xlfn.MAXIFS($B$5:$B$108,$B$5:$B$108,"<"&B7)=0,"",IF(INDEX($C$5:$C$108,MATCH(_xlfn.MAXIFS($B$5:$B$108,$B$5:$B$108,"<"&B7),$B$5:$B$108,0))="","",INDEX($C$5:$C$108,MATCH(_xlfn.MAXIFS($B$5:$B$108,$B$5:$B$108,"<"&B7),$B$5:$B$108,0))))) | N7: =IF(OR(C7="",M7=""),"",IF(MATCH(C7,{"Red","Amber","Green"},0)>MATCH(M7,{"Red","Amber","Green"},0),"▲ Improving",IF(MATCH(C7,{"Red","Amber","Green"},0)<MATCH(M7,{"Red","Amber","Green"},0),"▼ Deteriorating","► Stable")))
A8: WSR-004 | M8: =IF(B8="","",IF(_xlfn.MAXIFS($B$5:$B$108,$B$5:$B$108,"<"&B8)=0,"",IF(INDEX($C$5:$C$108,MATCH(_xlfn.MAXIFS($B$5:$B$108,$B$5:$B$108,"<"&B8),$B$5:$B$108,0))="","",INDEX($C$5:$C$108,MATCH(_xlfn.MAXIFS($B$5:$B$108,$B$5:$B$108,"<"&B8),$B$5:$B$108,0))))) | N8: =IF(OR(C8="",M8=""),"",IF(MATCH(C8,{"Red","Amber","Green"},0)>MATCH(M8,{"Red","Amber","Green"},0),"▲ Improving",IF(MATCH(C8,{"Red","Amber","Green"},0)<MATCH(M8,{"Red","Amber","Green"},0),"▼ Deteriorating","► Stable")))
A9: WSR-005 | M9: =IF(B9="","",IF(_xlfn.MAXIFS($B$5:$B$108,$B$5:$B$108,"<"&B9)=0,"",IF(INDEX($C$5:$C$108,MATCH(_xlfn.MAXIFS($B$5:$B$108,$B$5:$B$108,"<"&B9),$B$5:$B$108,0))="","",INDEX($C$5:$C$108,MATCH(_xlfn.MAXIFS($B$5:$B$108,$B$5:$B$108,"<"&B9),$B$5:$B$108,0))))) | N9: =IF(OR(C9="",M9=""),"",IF(MATCH(C9,{"Red","Amber","Green"},0)>MATCH(M9,{"Red","Amber","Green"},0),"▲ Improving",IF(MATCH(C9,{"Red","Amber","Green"},0)<MATCH(M9,{"Red","Amber","Green"},0),"▼ Deteriorating","► Stable")))
A10: WSR-006 | M10: =IF(B10="","",IF(_xlfn.MAXIFS($B$5:$B$108,$B$5:$B$108,"<"&B10)=0,"",IF(INDEX($C$5:$C$108,MATCH(_xlfn.MAXIFS($B$5:$B$108,$B$5:$B$108,"<"&B10),$B$5:$B$108,0))="","",INDEX($C$5:$C$108,MATCH(_xlfn.MAXIFS($B$5:$B$108,$B$5:$B$108,"<"&B10),$B$5:$B$108,0))))) | N10: =IF(OR(C10="",M10=""),"",IF(MATCH(C10,{"Red","Amber","Green"},0)>MATCH(M10,{"Red","Amber","Green"},0),"▲ Improving",IF(MATCH(C10,{"Red","Amber","Green"},0)<MATCH(M10,{"Red","Amber","Green"},0),"▼ Deteriorating","► Stable")))
A11: WSR-007 | M11: =IF(B11="","",IF(_xlfn.MAXIFS($B$5:$B$108,$B$5:$B$108,"<"&B11)=0,"",IF(INDEX($C$5:$C$108,MATCH(_xlfn.MAXIFS($B$5:$B$108,$B$5:$B$108,"<"&B11),$B$5:$B$108,0))="","",INDEX($C$5:$C$108,MATCH(_xlfn.MAXIFS($B$5:$B$108,$B$5:$B$108,"<"&B11),$B$5:$B$108,0))))) | N11: =IF(OR(C11="",M11=""),"",IF(MATCH(C11,{"Red","Amber","Green"},0)>MATCH(M11,{"Red","Amber","Green"},0),"▲ Improving",IF(MATCH(C11,{"Red","Amber","Green"},0)<MATCH(M11,{"Red","Amber","Green"},0),"▼ Deteriorating","► Stable")))
A12: WSR-008 | M12: =IF(B12="","",IF(_xlfn.MAXIFS($B$5:$B$108,$B$5:$B$108,"<"&B12)=0,"",IF(INDEX($C$5:$C$108,MATCH(_xlfn.MAXIFS($B$5:$B$108,$B$5:$B$108,"<"&B12),$B$5:$B$108,0))="","",INDEX($C$5:$C$108,MATCH(_xlfn.MAXIFS($B$5:$B$108,$B$5:$B$108,"<"&B12),$B$5:$B$108,0))))) | N12: =IF(OR(C12="",M12=""),"",IF(MATCH(C12,{"Red","Amber","Green"},0)>MATCH(M12,{"Red","Amber","Green"},0),"▲ Improving",IF(MATCH(C12,{"Red","Amber","Green"},0)<MATCH(M12,{"Red","Amber","Green"},0),"▼ Deteriorating","► Stable")))
A13: WSR-009 | M13: =IF(B13="","",IF(_xlfn.MAXIFS($B$5:$B$108,$B$5:$B$108,"<"&B13)=0,"",IF(INDEX($C$5:$C$108,MATCH(_xlfn.MAXIFS($B$5:$B$108,$B$5:$B$108,"<"&B13),$B$5:$B$108,0))="","",INDEX($C$5:$C$108,MATCH(_xlfn.MAXIFS($B$5:$B$108,$B$5:$B$108,"<"&B13),$B$5:$B$108,0))))) | N13: =IF(OR(C13="",M13=""),"",IF(MATCH(C13,{"Red","Amber","Green"},0)>MATCH(M13,{"Red","Amber","Green"},0),"▲ Improving",IF(MATCH(C13,{"Red","Amber","Green"},0)<MATCH(M13,{"Red","Amber","Green"},0),"▼ Deteriorating","► Stable")))
A14: WSR-010 | M14: =IF(B14="","",IF(_xlfn.MAXIFS($B$5:$B$108,$B$5:$B$108,"<"&B14)=0,"",IF(INDEX($C$5:$C$108,MATCH(_xlfn.MAXIFS($B$5:$B$108,$B$5:$B$108,"<"&B14),$B$5:$B$108,0))="","",INDEX($C$5:$C$108,MATCH(_xlfn.MAXIFS($B$5:$B$108,$B$5:$B$108,"<"&B14),$B$5:$B$108,0))))) | N14: =IF(OR(C14="",M14=""),"",IF(MATCH(C14,{"Red","Amber","Green"},0)>MATCH(M14,{"Red","Amber","Green"},0),"▲ Improving",IF(MATCH(C14,{"Red","Amber","Green"},0)<MATCH(M14,{"Red","Amber","Green"},0),"▼ Deteriorating","► Stable")))
A15: WSR-011 | M15: =IF(B15="","",IF(_xlfn.MAXIFS($B$5:$B$108,$B$5:$B$108,"<"&B15)=0,"",IF(INDEX($C$5:$C$108,MATCH(_xlfn.MAXIFS($B$5:$B$108,$B$5:$B$108,"<"&B15),$B$5:$B$108,0))="","",INDEX($C$5:$C$108,MATCH(_xlfn.MAXIFS($B$5:$B$108,$B$5:$B$108,"<"&B15),$B$5:$B$108,0))))) | N15: =IF(OR(C15="",M15=""),"",IF(MATCH(C15,{"Red","Amber","Green"},0)>MATCH(M15,{"Red","Amber","Green"},0),"▲ Improving",IF(MATCH(C15,{"Red","Amber","Green"},0)<MATCH(M15,{"Red","Amber","Green"},0),"▼ Deteriorating","► Stable")))
A16: WSR-012 | M16: =IF(B16="","",IF(_xlfn.MAXIFS($B$5:$B$108,$B$5:$B$108,"<"&B16)=0,"",IF(INDEX($C$5:$C$108,MATCH(_xlfn.MAXIFS($B$5:$B$108,$B$5:$B$108,"<"&B16),$B$5:$B$108,0))="","",INDEX($C$5:$C$108,MATCH(_xlfn.MAXIFS($B$5:$B$108,$B$5:$B$108,"<"&B16),$B$5:$B$108,0))))) | N16: =IF(OR(C16="",M16=""),"",IF(MATCH(C16,{"Red","Amber","Green"},0)>MATCH(M16,{"Red","Amber","Green"},0),"▲ Improving",IF(MATCH(C16,{"Red","Amber","Green"},0)<MATCH(M16,{"Red","Amber","Green"},0),"▼ Deteriorating","► Stable")))
A17: WSR-013 | M17: =IF(B17="","",IF(_xlfn.MAXIFS($B$5:$B$108,$B$5:$B$108,"<"&B17)=0,"",IF(INDEX($C$5:$C$108,MATCH(_xlfn.MAXIFS($B$5:$B$108,$B$5:$B$108,"<"&B17),$B$5:$B$108,0))="","",INDEX($C$5:$C$108,MATCH(_xlfn.MAXIFS($B$5:$B$108,$B$5:$B$108,"<"&B17),$B$5:$B$108,0))))) | N17: =IF(OR(C17="",M17=""),"",IF(MATCH(C17,{"Red","Amber","Green"},0)>MATCH(M17,{"Red","Amber","Green"},0),"▲ Improving",IF(MATCH(C17,{"Red","Amber","Green"},0)<MATCH(M17,{"Red","Amber","Green"},0),"▼ Deteriorating","► Stable")))
... A108: WSR-104 | M108: =IF(B108="","",IF(_xlfn.MAXIFS($B$5:$B$108,$B$5:$B$108,"<"&B108)=0,"",IF(INDEX($C$5:$C$108,MATCH(_xlfn.MAXIFS($B$5:$B$108,$B$5:$B$108,"<"&B108),$B$5:$B$108,0))="","",INDEX($C$5:$C$108,MATCH(_xlfn.MAXIFS($B$5:$B$108,$B$5:$B$108,"<"&B108),$B$5:$B$108,0))))) | N108: =IF(OR(C108="",M108=""),"",IF(MATCH(C108,{"Red","Amber","Green"},0)>MATCH(M108,{"Red","Amber","Green"},0),"▲ Improving",IF(MATCH(C108,{"Red","Amber","Green"},0)<MATCH(M108,{"Red","Amber","Green"},0),"▼ Deteriorating","► Stable")))

Sheet Dashboard
A1: EASM Mission Dashboard
A2: As of | B2: =TODAY() -> 46315 | D2: All figures calculate automatically from the log tabs. Do not type here.
A4: Weekly Status | D4: Tasks by Status | E4: Count
A5: Reported RAG (latest weekly meeting) | B5: ='Weekly Report'!C26 -> Amber | D5: Not Started | E5: =COUNTIFS(Tasks!$F$5:$F$304,"<>",Tasks!$K$5:$K$304,D5) -> 0
A6: Indicator-based RAG | B6: ='Weekly Report'!C28 -> Amber | D6: In Progress | E6: =COUNTIFS(Tasks!$F$5:$F$304,"<>",Tasks!$K$5:$K$304,D6) -> 1
A7: Trend vs previous week | B7: ='Weekly Report'!D27 | D7: Blocked | E7: =COUNTIFS(Tasks!$F$5:$F$304,"<>",Tasks!$K$5:$K$304,D7) -> 0
D8: On Hold | E8: =COUNTIFS(Tasks!$F$5:$F$304,"<>",Tasks!$K$5:$K$304,D8) -> 0
A9: Mission Timeline | D9: Completed | E9: =COUNTIFS(Tasks!$F$5:$F$304,"<>",Tasks!$K$5:$K$304,D9) -> 0
A10: Days elapsed | B10: ='Mission Charter'!B11 -> 19 | D10: Cancelled | E10: =COUNTIFS(Tasks!$F$5:$F$304,"<>",Tasks!$K$5:$K$304,D10) -> 0
A11: Days remaining | B11: ='Mission Charter'!B12 -> 162
A12: % of timeline elapsed | B12: ='Mission Charter'!B13 -> 0.10497238 | D12: Findings by Severity | E12: Count | F12: Open
D13: Critical | E13: =COUNTIFS('EASM Findings'!$E$5:$E$304,"<>",'EASM Findings'!$L$5:$L$304,D13) -> 1 | F13: =COUNTIFS('EASM Findings'!$E$5:$E$304,"<>",'EASM Findings'!$U$5:$U$304,"<>Remediated",'EASM Findings'!$U$5:$U$304,"<>False Positive",'EASM Findings'!$U$5:$U$304,"<>Risk Accepted",'EASM Findings'!$L$5:$L$304,D13) -> 1
A14: Meetings | D14: High | E14: =COUNTIFS('EASM Findings'!$E$5:$E$304,"<>",'EASM Findings'!$L$5:$L$304,D14) -> 0 | F14: =COUNTIFS('EASM Findings'!$E$5:$E$304,"<>",'EASM Findings'!$U$5:$U$304,"<>Remediated",'EASM Findings'!$U$5:$U$304,"<>False Positive",'EASM Findings'!$U$5:$U$304,"<>Risk Accepted",'EASM Findings'!$L$5:$L$304,D14) -> 0
A15: Meetings logged | B15: =COUNTA(Meetings!$G$5:$G$304) -> 1 | D15: Medium | E15: =COUNTIFS('EASM Findings'!$E$5:$E$304,"<>",'EASM Findings'!$L$5:$L$304,D15) -> 0 | F15: =COUNTIFS('EASM Findings'!$E$5:$E$304,"<>",'EASM Findings'!$U$5:$U$304,"<>Remediated",'EASM Findings'!$U$5:$U$304,"<>False Positive",'EASM Findings'!$U$5:$U$304,"<>Risk Accepted",'EASM Findings'!$L$5:$L$304,D15) -> 0
A16: Meetings in last 30 days | B16: =COUNTIFS(Meetings!$G$5:$G$304,"<>",Meetings!$B$5:$B$304,">="&(TODAY()-30)) -> 1 | D16: Low | E16: =COUNTIFS('EASM Findings'!$E$5:$E$304,"<>",'EASM Findings'!$L$5:$L$304,D16) -> 0 | F16: =COUNTIFS('EASM Findings'!$E$5:$E$304,"<>",'EASM Findings'!$U$5:$U$304,"<>Remediated",'EASM Findings'!$U$5:$U$304,"<>False Positive",'EASM Findings'!$U$5:$U$304,"<>Risk Accepted",'EASM Findings'!$L$5:$L$304,D16) -> 0
A17: Overdue follow-ups | B17: =COUNTIF(Meetings!$T$5:$T$304,"OVERDUE") -> 0 | D17: Informational | E17: =COUNTIFS('EASM Findings'!$E$5:$E$304,"<>",'EASM Findings'!$L$5:$L$304,D17) -> 0 | F17: =COUNTIFS('EASM Findings'!$E$5:$E$304,"<>",'EASM Findings'!$U$5:$U$304,"<>Remediated",'EASM Findings'!$U$5:$U$304,"<>False Positive",'EASM Findings'!$U$5:$U$304,"<>Risk Accepted",'EASM Findings'!$L$5:$L$304,D17) -> 0
A19: Emails & Communications | D19: Findings by Status | E19: Count
A20: Emails logged | B20: =COUNTA(Emails!$G$5:$G$304) -> 1 | D20: New | E20: =COUNTIFS('EASM Findings'!$E$5:$E$304,"<>",'EASM Findings'!$U$5:$U$304,D20) -> 0
A21: Awaiting response | B21: =COUNT(Emails!$V$5:$V$304) -> 1 | D21: Validating | E21: =COUNTIFS('EASM Findings'!$E$5:$E$304,"<>",'EASM Findings'!$U$5:$U$304,D21) -> 1
A22: Overdue responses | B22: =COUNTIF(Emails!$R$5:$R$304,"OVERDUE") -> 0 | D22: Confirmed | E22: =COUNTIFS('EASM Findings'!$E$5:$E$304,"<>",'EASM Findings'!$U$5:$U$304,D22) -> 0
A23: Average days to respond | B23: =IFERROR(AVERAGE(Emails!$Q$5:$Q$304),"-") -> - | D23: Remediation In Progress | E23: =COUNTIFS('EASM Findings'!$E$5:$E$304,"<>",'EASM Findings'!$U$5:$U$304,D23) -> 0
A24: Escalations | B24: =COUNTIF(Emails!$H$5:$H$304,"Escalation")+COUNTIF(Emails!$O$5:$O$304,"Escalated") -> 0 | D24: Remediated | E24: =COUNTIFS('EASM Findings'!$E$5:$E$304,"<>",'EASM Findings'!$U$5:$U$304,D24) -> 0
D25: Risk Accepted | E25: =COUNTIFS('EASM Findings'!$E$5:$E$304,"<>",'EASM Findings'!$U$5:$U$304,D25) -> 0
A26: Tasks | D26: False Positive | E26: =COUNTIFS('EASM Findings'!$E$5:$E$304,"<>",'EASM Findings'!$U$5:$U$304,D26) -> 0
A27: Tasks logged | B27: =COUNTA(Tasks!$F$5:$F$304) -> 1
A28: Open tasks | B28: =COUNTIFS(Tasks!$F$5:$F$304,"<>",Tasks!$K$5:$K$304,"<>Completed",Tasks!$K$5:$K$304,"<>Cancelled") -> 1 | D28: Goals by Status | E28: Count
A29: Overdue tasks | B29: =COUNTIF(Tasks!$X$5:$X$304,"OVERDUE") -> 0 | D29: On Track | E29: =COUNTIFS('Goals & KPIs'!$B$5:$B$304,"<>",'Goals & KPIs'!$P$5:$P$304,D29) -> 1
A30: Due within 7 days | B30: =COUNTIF(Tasks!$X$5:$X$304,"Due*") -> 0 | D30: At Risk | E30: =COUNTIFS('Goals & KPIs'!$B$5:$B$304,"<>",'Goals & KPIs'!$P$5:$P$304,D30) -> 0
A31: Blocked tasks | B31: =COUNTIF(Tasks!$K$5:$K$304,"Blocked") -> 0 | D31: Off Track | E31: =COUNTIFS('Goals & KPIs'!$B$5:$B$304,"<>",'Goals & KPIs'!$P$5:$P$304,D31) -> 0
A32: Completion rate (excl. cancelled) | B32: =IFERROR(COUNTIF(Tasks!$K$5:$K$304,"Completed")/(COUNTA(Tasks!$F$5:$F$304)-COUNTIF(Tasks!$K$5:$K$304,"Cancelled")),0) -> 0 | D32: Achieved | E32: =COUNTIFS('Goals & KPIs'!$B$5:$B$304,"<>",'Goals & KPIs'!$P$5:$P$304,D32) -> 0
D33: Deferred | E33: =COUNTIFS('Goals & KPIs'!$B$5:$B$304,"<>",'Goals & KPIs'!$P$5:$P$304,D33) -> 0
A34: Goals & KPIs
A35: Goals defined | B35: =COUNTA('Goals & KPIs'!$B$5:$B$304) -> 1 | D35: Meetings by Type | E35: Count
A36: Average progress to target | B36: =IFERROR(AVERAGE('Goals & KPIs'!$L$5:$L$304),"-") -> 0.24242424 | D36: Weekly Status Meeting | E36: =COUNTIFS(Meetings!$G$5:$G$304,"<>",Meetings!$E$5:$E$304,D36) -> 0
A37: Goals At Risk / Off Track | B37: =COUNTIF('Goals & KPIs'!$P$5:$P$304,"At Risk")+COUNTIF('Goals & KPIs'!$P$5:$P$304,"Off Track") -> 0 | D37: Kick-off | E37: =COUNTIFS(Meetings!$G$5:$G$304,"<>",Meetings!$E$5:$E$304,D37) -> 0
A38: Goals achieved | B38: =COUNTIF('Goals & KPIs'!$P$5:$P$304,"Achieved") -> 0 | D38: Steering Committee | E38: =COUNTIFS(Meetings!$G$5:$G$304,"<>",Meetings!$E$5:$E$304,D38) -> 0
D39: Working Session | E39: =COUNTIFS(Meetings!$G$5:$G$304,"<>",Meetings!$E$5:$E$304,D39) -> 1
A40: EASM Findings | D40: 1LoD Challenge Session | E40: =COUNTIFS(Meetings!$G$5:$G$304,"<>",Meetings!$E$5:$E$304,D40) -> 0
A41: Findings logged | B41: =COUNTA('EASM Findings'!$E$5:$E$304) -> 1 | D41: Stakeholder Interview | E41: =COUNTIFS(Meetings!$G$5:$G$304,"<>",Meetings!$E$5:$E$304,D41) -> 0
A42: Open findings | B42: =COUNTIFS('EASM Findings'!$E$5:$E$304,"<>",'EASM Findings'!$U$5:$U$304,"<>Remediated",'EASM Findings'!$U$5:$U$304,"<>False Positive",'EASM Findings'!$U$5:$U$304,"<>Risk Accepted") -> 1 | D42: Vendor / Tooling | E42: =COUNTIFS(Meetings!$G$5:$G$304,"<>",Meetings!$E$5:$E$304,D42) -> 0
...

Sheet Mission Charter
A1: EASM Mission Charter
A2: Fill once at mission start; update when scope, timeline or governance changes. The phase plan drives the Weekly Report timeline.
A5: Mission name | B5: External Attack Surface Management (EASM) – 2LoD Assessment
A6: Mission reference
A7: Mission sponsor
A8: Mission lead (2LoD CRI)
A9: Start date | B9: 46296
A10: Planned end date | B10: 46477
A11: Days elapsed | B11: =IF(B9="","",TODAY()-B9) -> 19
A12: Days remaining | B12: =IF(B10="","",B10-TODAY()) -> 162
A13: % of timeline elapsed | B13: =IF(OR(B9="",B10="",B10=B9),"",MAX(0,MIN(1,(TODAY()-B9)/(B10-B9)))) -> 0.10497238
A14: Mission objective
A15: In scope (entities, domains, IP ranges, cloud tenants)
A16: Out of scope
A17: Regulatory / supervisory drivers | B17: e.g. DORA ICT asset identification, supervisory expectations, internal audit points
A18: RAF metrics / KRIs linked
A19: EASM tooling & data sources
A20: 1LoD counterparts
A21: Governance forum & weekly meeting cadence
A22: Key assumptions
A23: Constraints / limitations
A24: Success criteria
A26: Phase Plan
A27: Phase | B27: Description | C27: Planned Start | D27: Planned End | E27: Actual End | F27: Status | G27: Variance (days)
A28: 1. Scoping & Baseline | B28: Confirm entities, seeds (domains, ASNs, IP ranges, cloud tenants) and tooling | C28: 46296 | D28: 46312 | E28: 46311 | F28: Completed | G28: =IF(OR(D28="",E28=""),"",E28-D28) -> -1
A29: 2. Discovery & Attribution | B29: Run discovery; attribute assets to owners and legal entities; reconcile vs CMDB | C29: 46307 | D29: 46340 | F29: In Progress | G29: =IF(OR(D29="",E29=""),"",E29-D29)
A30: 3. Exposure Assessment | B30: Identify exposed services, vulnerabilities, misconfigurations, leaked credentials | C30: 46328 | D30: 46375 | F30: Not Started | G30: =IF(OR(D30="",E30=""),"",E30-D30)
A31: 4. Risk Translation & 1LoD Challenge | B31: Translate exposures into operational, systemic, financial and RAF impact; challenge 1LoD premises | C31: 46356 | D31: 46416 | F31: Not Started | G31: =IF(OR(D31="",E31=""),"",E31-D31)
A32: 5. Remediation Oversight | B32: Track remediation against SLAs; review risk acceptances | C32: 46391 | D32: 46458 | F32: Not Started | G32: =IF(OR(D32="",E32=""),"",E32-D32)
A33: 6. Reporting & Closure | B33: Committee reporting, lessons learned, transition to BAU monitoring | C33: 46447 | D33: 46477 | F33: Not Started | G33: =IF(OR(D33="",E33=""),"",E33-D33)
A35: Phase dates in italic are illustrative — replace with your plan.

Sheet Goals & KPIs
A1: Goals & KPIs
A2: Mission objectives and measurable key results — week-on-week movement and automatic progress.
A3: White cells = your input | Grey cells = automatic (do not overwrite) | Row 5 is an illustrative example (italic) — overwrite or delete it.
A4: Goal ID | B4: Goal / Objective | C4: Workstream | D4: Key Result / KPI | E4: Metric Definition | F4: Unit | G4: Baseline | H4: Target | I4: Value Last Week | J4: Current Value | K4: Δ vs Last Week | L4: Progress to Target | M4: Owner | N4: Target Date | O4: Days to Target | P4: Status | Q4: RAF Linkage (KRI / Limit) | R4: Last Updated | S4: Commentary | T4: WR helper: updated
A5: GOL-001 | B5: Establish a complete, attributed inventory of internet-facing assets | C5: Attribution & Ownership | D5: % of discovered internet-facing assets attributed to an accountable owner | E5: Attributed assets ÷ total discovered assets (EASM platform, weekly snapshot) | F5: % | G5: 62 | H5: 95 | I5: 66 | J5: 70 | K5: =IF(OR(J5="",I5=""),"",J5-I5) -> 4 | L5: =IF(OR(G5="",H5="",J5=""),"",IF(H5=G5,"",MAX(0,MIN(1,(J5-G5)/(H5-G5))))) -> 0.24242424 | M5: Me (2LoD CRI) | N5: 46387 | O5: =IF(N5="","",N5-TODAY()) -> 72 | P5: On Track | Q5: Cyber RAF – ICT asset management KRI | R5: 46314 | S5: Uplift from Entity A reconciliation; Entity C extract outstanding (TSK-001) | T5: =IF(AND(B5<>"",AND(R5<>"",R5>='Weekly Report'!$F$4,R5<='Weekly Report'!$F$5)),ROW(),"") -> 5
A6: GOL-002 | K6: =IF(OR(J6="",I6=""),"",J6-I6) | L6: =IF(OR(G6="",H6="",J6=""),"",IF(H6=G6,"",MAX(0,MIN(1,(J6-G6)/(H6-G6))))) | O6: =IF(N6="","",N6-TODAY()) | T6: =IF(AND(B6<>"",AND(R6<>"",R6>='Weekly Report'!$F$4,R6<='Weekly Report'!$F$5)),ROW(),"")
A7: GOL-003 | K7: =IF(OR(J7="",I7=""),"",J7-I7) | L7: =IF(OR(G7="",H7="",J7=""),"",IF(H7=G7,"",MAX(0,MIN(1,(J7-G7)/(H7-G7))))) | O7: =IF(N7="","",N7-TODAY()) | T7: =IF(AND(B7<>"",AND(R7<>"",R7>='Weekly Report'!$F$4,R7<='Weekly Report'!$F$5)),ROW(),"")
A8: GOL-004 | K8: =IF(OR(J8="",I8=""),"",J8-I8) | L8: =IF(OR(G8="",H8="",J8=""),"",IF(H8=G8,"",MAX(0,MIN(1,(J8-G8)/(H8-G8))))) | O8: =IF(N8="","",N8-TODAY()) | T8: =IF(AND(B8<>"",AND(R8<>"",R8>='Weekly Report'!$F$4,R8<='Weekly Report'!$F$5)),ROW(),"")
A9: GOL-005 | K9: =IF(OR(J9="",I9=""),"",J9-I9) | L9: =IF(OR(G9="",H9="",J9=""),"",IF(H9=G9,"",MAX(0,MIN(1,(J9-G9)/(H9-G9))))) | O9: =IF(N9="","",N9-TODAY()) | T9: =IF(AND(B9<>"",AND(R9<>"",R9>='Weekly Report'!$F$4,R9<='Weekly Report'!$F$5)),ROW(),"")
A10: GOL-006 | K10: =IF(OR(J10="",I10=""),"",J10-I10) | L10: =IF(OR(G10="",H10="",J10=""),"",IF(H10=G10,"",MAX(0,MIN(1,(J10-G10)/(H10-G10))))) | O10: =IF(N10="","",N10-TODAY()) | T10: =IF(AND(B10<>"",AND(R10<>"",R10>='Weekly Report'!$F$4,R10<='Weekly Report'!$F$5)),ROW(),"")
A11: GOL-007 | K11: =IF(OR(J11="",I11=""),"",J11-I11) | L11: =IF(OR(G11="",H11="",J11=""),"",IF(H11=G11,"",MAX(0,MIN(1,(J11-G11)/(H11-G11))))) | O11: =IF(N11="","",N11-TODAY()) | T11: =IF(AND(B11<>"",AND(R11<>"",R11>='Weekly Report'!$F$4,R11<='Weekly Report'!$F$5)),ROW(),"")
A12: GOL-008 | K12: =IF(OR(J12="",I12=""),"",J12-I12) | L12: =IF(OR(G12="",H12="",J12=""),"",IF(H12=G12,"",MAX(0,MIN(1,(J12-G12)/(H12-G12))))) | O12: =IF(N12="","",N12-TODAY()) | T12: =IF(AND(B12<>"",AND(R12<>"",R12>='Weekly Report'!$F$4,R12<='Weekly Report'!$F$5)),ROW(),"")
A13: GOL-009 | K13: =IF(OR(J13="",I13=""),"",J13-I13) | L13: =IF(OR(G13="",H13="",J13=""),"",IF(H13=G13,"",MAX(0,MIN(1,(J13-G13)/(H13-G13))))) | O13: =IF(N13="","",N13-TODAY()) | T13: =IF(AND(B13<>"",AND(R13<>"",R13>='Weekly Report'!$F$4,R13<='Weekly Report'!$F$5)),ROW(),"")
A14: GOL-010 | K14: =IF(OR(J14="",I14=""),"",J14-I14) | L14: =IF(OR(G14="",H14="",J14=""),"",IF(H14=G14,"",MAX(0,MIN(1,(J14-G14)/(H14-G14))))) | O14: =IF(N14="","",N14-TODAY()) | T14: =IF(AND(B14<>"",AND(R14<>"",R14>='Weekly Report'!$F$4,R14<='Weekly Report'!$F$5)),ROW(),"")
A15: GOL-011 | K15: =IF(OR(J15="",I15=""),"",J15-I15) | L15: =IF(OR(G15="",H15="",J15=""),"",IF(H15=G15,"",MAX(0,MIN(1,(J15-G15)/(H15-G15))))) | O15: =IF(N15="","",N15-TODAY()) | T15: =IF(AND(B15<>"",AND(R15<>"",R15>='Weekly Report'!$F$4,R15<='Weekly Report'!$F$5)),ROW(),"")
A16: GOL-012 | K16: =IF(OR(J16="",I16=""),"",J16-I16) | L16: =IF(OR(G16="",H16="",J16=""),"",IF(H16=G16,"",MAX(0,MIN(1,(J16-G16)/(H16-G16))))) | O16: =IF(N16="","",N16-TODAY()) | T16: =IF(AND(B16<>"",AND(R16<>"",R16>='Weekly Report'!$F$4,R16<='Weekly Report'!$F$5)),ROW(),"")
A17: GOL-013 | K17: =IF(OR(J17="",I17=""),"",J17-I17) | L17: =IF(OR(G17="",H17="",J17=""),"",IF(H17=G17,"",MAX(0,MIN(1,(J17-G17)/(H17-G17))))) | O17: =IF(N17="","",N17-TODAY()) | T17: =IF(AND(B17<>"",AND(R17<>"",R17>='Weekly Report'!$F$4,R17<='Weekly Report'!$F$5)),ROW(),"")
... A304: GOL-300 | K304: =IF(OR(J304="",I304=""),"",J304-I304) | L304: =IF(OR(G304="",H304="",J304=""),"",IF(H304=G304,"",MAX(0,MIN(1,(J304-G304)/(H304-G304))))) | O304: =IF(N304="","",N304-TODAY()) | T304: =IF(AND(B304<>"",AND(R304<>"",R304>='Weekly Report'!$F$4,R304<='Weekly Report'!$F$5)),ROW(),"")

Sheet Meetings
A1: Meetings Log
A2: Every meeting held under the EASM mission: participants, decisions, 2LoD challenge and follow-ups.
A3: White cells = your input | Grey cells = automatic (do not overwrite) | Row 5 is an illustrative example (italic) — overwrite or delete it.
A4: Meeting ID | B4: Date | C4: Start Time | D4: Duration (min) | E4: Meeting Type | F4: Workstream | G4: Title / Subject | H4: Organiser | I4: Attendees (name – function) | J4: LoD Represented | K4: Agenda / Purpose | L4: Key Discussion Points | M4: Decisions Taken | N4: 2LoD Challenge Raised | O4: 1LoD Position / Response | P4: Actions Generated (Task IDs) | Q4: Follow-up Required? | R4: Follow-up Date | S4: Follow-up Completed? | T4: Follow-up Flag | U4: Minutes / Recording Link | V4: Classification | W4: Notes | X4: WR helper: held in period
A5: MTG-001 | B5: 46310 | C5: 0.41666667 | D5: 60 | E5: Working Session | F5: Asset Discovery | G5: EASM baseline – scope validation with Group Infrastructure | H5: Me (2LoD CRI) | I5: Head of Network Security; CISO Office; Group Architecture | J5: Multiple | K5: Validate in-scope legal entities, IP ranges and root domains for EASM baseline | L5: EASM platform shows ~18% of discovered hosts not mapped in CMDB; 3 recently acquired entities not onboarded | M5: Scope extension to 3 acquired entities proposed to Mission Sponsor (DEV-001) | N5: 1LoD claim of 95% inventory completeness not evidenced; reconciliation requested | O5: 1LoD to provide CMDB extract of internet-facing assets | P5: TSK-001 | Q5: Yes | R5: 46325 | S5: No | T5: =IF(Q5<>"Yes","",IF(S5="Yes","Done",IF(R5="","Date missing",IF(R5<TODAY(),"OVERDUE","Scheduled")))) -> Scheduled | U5: SharePoint/EASM/Minutes/MTG-001 | V5: Confidential | X5: =IF(AND(G5<>"",AND(B5<>"",B5>='Weekly Report'!$F$4,B5<='Weekly Report'!$F$5)),ROW(),"") -> 5
A6: MTG-002 | T6: =IF(Q6<>"Yes","",IF(S6="Yes","Done",IF(R6="","Date missing",IF(R6<TODAY(),"OVERDUE","Scheduled")))) | X6: =IF(AND(G6<>"",AND(B6<>"",B6>='Weekly Report'!$F$4,B6<='Weekly Report'!$F$5)),ROW(),"")
A7: MTG-003 | T7: =IF(Q7<>"Yes","",IF(S7="Yes","Done",IF(R7="","Date missing",IF(R7<TODAY(),"OVERDUE","Scheduled")))) | X7: =IF(AND(G7<>"",AND(B7<>"",B7>='Weekly Report'!$F$4,B7<='Weekly Report'!$F$5)),ROW(),"")
A8: MTG-004 | T8: =IF(Q8<>"Yes","",IF(S8="Yes","Done",IF(R8="","Date missing",IF(R8<TODAY(),"OVERDUE","Scheduled")))) | X8: =IF(AND(G8<>"",AND(B8<>"",B8>='Weekly Report'!$F$4,B8<='Weekly Report'!$F$5)),ROW(),"")
A9: MTG-005 | T9: =IF(Q9<>"Yes","",IF(S9="Yes","Done",IF(R9="","Date missing",IF(R9<TODAY(),"OVERDUE","Scheduled")))) | X9: =IF(AND(G9<>"",AND(B9<>"",B9>='Weekly Report'!$F$4,B9<='Weekly Report'!$F$5)),ROW(),"")
A10: MTG-006 | T10: =IF(Q10<>"Yes","",IF(S10="Yes","Done",IF(R10="","Date missing",IF(R10<TODAY(),"OVERDUE","Scheduled")))) | X10: =IF(AND(G10<>"",AND(B10<>"",B10>='Weekly Report'!$F$4,B10<='Weekly Report'!$F$5)),ROW(),"")
A11: MTG-007 | T11: =IF(Q11<>"Yes","",IF(S11="Yes","Done",IF(R11="","Date missing",IF(R11<TODAY(),"OVERDUE","Scheduled")))) | X11: =IF(AND(G11<>"",AND(B11<>"",B11>='Weekly Report'!$F$4,B11<='Weekly Report'!$F$5)),ROW(),"")
A12: MTG-008 | T12: =IF(Q12<>"Yes","",IF(S12="Yes","Done",IF(R12="","Date missing",IF(R12<TODAY(),"OVERDUE","Scheduled")))) | X12: =IF(AND(G12<>"",AND(B12<>"",B12>='Weekly Report'!$F$4,B12<='Weekly Report'!$F$5)),ROW(),"")
A13: MTG-009 | T13: =IF(Q13<>"Yes","",IF(S13="Yes","Done",IF(R13="","Date missing",IF(R13<TODAY(),"OVERDUE","Scheduled")))) | X13: =IF(AND(G13<>"",AND(B13<>"",B13>='Weekly Report'!$F$4,B13<='Weekly Report'!$F$5)),ROW(),"")
A14: MTG-010 | T14: =IF(Q14<>"Yes","",IF(S14="Yes","Done",IF(R14="","Date missing",IF(R14<TODAY(),"OVERDUE","Scheduled")))) | X14: =IF(AND(G14<>"",AND(B14<>"",B14>='Weekly Report'!$F$4,B14<='Weekly Report'!$F$5)),ROW(),"")
A15: MTG-011 | T15: =IF(Q15<>"Yes","",IF(S15="Yes","Done",IF(R15="","Date missing",IF(R15<TODAY(),"OVERDUE","Scheduled")))) | X15: =IF(AND(G15<>"",AND(B15<>"",B15>='Weekly Report'!$F$4,B15<='Weekly Report'!$F$5)),ROW(),"")
A16: MTG-012 | T16: =IF(Q16<>"Yes","",IF(S16="Yes","Done",IF(R16="","Date missing",IF(R16<TODAY(),"OVERDUE","Scheduled")))) | X16: =IF(AND(G16<>"",AND(B16<>"",B16>='Weekly Report'!$F$4,B16<='Weekly Report'!$F$5)),ROW(),"")
A17: MTG-013 | T17: =IF(Q17<>"Yes","",IF(S17="Yes","Done",IF(R17="","Date missing",IF(R17<TODAY(),"OVERDUE","Scheduled")))) | X17: =IF(AND(G17<>"",AND(B17<>"",B17>='Weekly Report'!$F$4,B17<='Weekly Report'!$F$5)),ROW(),"")
... A304: MTG-300 | T304: =IF(Q304<>"Yes","",IF(S304="Yes","Done",IF(R304="","Date missing",IF(R304<TODAY(),"OVERDUE","Scheduled")))) | X304: =IF(AND(G304<>"",AND(B304<>"",B304>='Weekly Report'!$F$4,B304<='Weekly Report'!$F$5)),ROW(),"")

Sheet Emails
A1: Email & Communications Log
A2: Material emails sent/received: requests, evidence, escalations and response SLAs.
A3: White cells = your input | Grey cells = automatic (do not overwrite) | Row 5 is an illustrative example (italic) — overwrite or delete it.
A4: Email ID | B4: Date Sent / Received | C4: Direction | D4: From | E4: To / Cc | F4: Counterparty LoD | G4: Subject | H4: Category | I4: Workstream | J4: Summary | K4: Request / Ask | L4: Attachments / Evidence | M4: Response Required? | N4: Response Due | O4: Response Status | P4: Date Responded | Q4: Days to Respond | R4: Response Flag | S4: Linked IDs (MTG/TSK/FND) | T4: Mail Reference / Link | U4: Notes | V4: WR helper: response awaited
A5: EML-001 | B5: 46311 | C5: Outbound | D5: Me (2LoD CRI) | E5: Head of Network Security; cc CISO Office | F5: 1LoD | G5: RFI – CMDB extract of internet-facing assets | H5: Request for Information | I5: Attribution & Ownership | J5: Formal request following MTG-001 for the CMDB extract to reconcile against EASM discovery output | K5: Full extract incl. owner, legal entity, hosting and last patch date | L5: None | M5: Yes | N5: 46318 | O5: Awaiting Response | Q5: =IF(OR(B5="",P5=""),"",P5-B5) | R5: =IF(OR(M5<>"Yes",P5<>"",O5="Closed",O5="No Action Required"),"",IF(N5="","Due date missing",IF(N5<TODAY(),"OVERDUE",IF(N5-TODAY()<=2,"Due ≤2d","Open")))) -> Open | S5: MTG-001; TSK-001 | T5: Outlook – EASM folder | V5: =IF(AND(G5<>"",M5="Yes",P5="",O5<>"Closed",O5<>"No Action Required",O5<>"Responded"),ROW(),"") -> 5
A6: EML-002 | Q6: =IF(OR(B6="",P6=""),"",P6-B6) | R6: =IF(OR(M6<>"Yes",P6<>"",O6="Closed",O6="No Action Required"),"",IF(N6="","Due date missing",IF(N6<TODAY(),"OVERDUE",IF(N6-TODAY()<=2,"Due ≤2d","Open")))) | V6: =IF(AND(G6<>"",M6="Yes",P6="",O6<>"Closed",O6<>"No Action Required",O6<>"Responded"),ROW(),"")
A7: EML-003 | Q7: =IF(OR(B7="",P7=""),"",P7-B7) | R7: =IF(OR(M7<>"Yes",P7<>"",O7="Closed",O7="No Action Required"),"",IF(N7="","Due date missing",IF(N7<TODAY(),"OVERDUE",IF(N7-TODAY()<=2,"Due ≤2d","Open")))) | V7: =IF(AND(G7<>"",M7="Yes",P7="",O7<>"Closed",O7<>"No Action Required",O7<>"Responded"),ROW(),"")
A8: EML-004 | Q8: =IF(OR(B8="",P8=""),"",P8-B8) | R8: =IF(OR(M8<>"Yes",P8<>"",O8="Closed",O8="No Action Required"),"",IF(N8="","Due date missing",IF(N8<TODAY(),"OVERDUE",IF(N8-TODAY()<=2,"Due ≤2d","Open")))) | V8: =IF(AND(G8<>"",M8="Yes",P8="",O8<>"Closed",O8<>"No Action Required",O8<>"Responded"),ROW(),"")
A9: EML-005 | Q9: =IF(OR(B9="",P9=""),"",P9-B9) | R9: =IF(OR(M9<>"Yes",P9<>"",O9="Closed",O9="No Action Required"),"",IF(N9="","Due date missing",IF(N9<TODAY(),"OVERDUE",IF(N9-TODAY()<=2,"Due ≤2d","Open")))) | V9: =IF(AND(G9<>"",M9="Yes",P9="",O9<>"Closed",O9<>"No Action Required",O9<>"Responded"),ROW(),"")
A10: EML-006 | Q10: =IF(OR(B10="",P10=""),"",P10-B10) | R10: =IF(OR(M10<>"Yes",P10<>"",O10="Closed",O10="No Action Required"),"",IF(N10="","Due date missing",IF(N10<TODAY(),"OVERDUE",IF(N10-TODAY()<=2,"Due ≤2d","Open")))) | V10: =IF(AND(G10<>"",M10="Yes",P10="",O10<>"Closed",O10<>"No Action Required",O10<>"Responded"),ROW(),"")
A11: EML-007 | Q11: =IF(OR(B11="",P11=""),"",P11-B11) | R11: =IF(OR(M11<>"Yes",P11<>"",O11="Closed",O11="No Action Required"),"",IF(N11="","Due date missing",IF(N11<TODAY(),"OVERDUE",IF(N11-TODAY()<=2,"Due ≤2d","Open")))) | V11: =IF(AND(G11<>"",M11="Yes",P11="",O11<>"Closed",O11<>"No Action Required",O11<>"Responded"),ROW(),"")
A12: EML-008 | Q12: =IF(OR(B12="",P12=""),"",P12-B12) | R12: =IF(OR(M12<>"Yes",P12<>"",O12="Closed",O12="No Action Required"),"",IF(N12="","Due date missing",IF(N12<TODAY(),"OVERDUE",IF(N12-TODAY()<=2,"Due ≤2d","Open")))) | V12: =IF(AND(G12<>"",M12="Yes",P12="",O12<>"Closed",O12<>"No Action Required",O12<>"Responded"),ROW(),"")
A13: EML-009 | Q13: =IF(OR(B13="",P13=""),"",P13-B13) | R13: =IF(OR(M13<>"Yes",P13<>"",O13="Closed",O13="No Action Required"),"",IF(N13="","Due date missing",IF(N13<TODAY(),"OVERDUE",IF(N13-TODAY()<=2,"Due ≤2d","Open")))) | V13: =IF(AND(G13<>"",M13="Yes",P13="",O13<>"Closed",O13<>"No Action Required",O13<>"Responded"),ROW(),"")
A14: EML-010 | Q14: =IF(OR(B14="",P14=""),"",P14-B14) | R14: =IF(OR(M14<>"Yes",P14<>"",O14="Closed",O14="No Action Required"),"",IF(N14="","Due date missing",IF(N14<TODAY(),"OVERDUE",IF(N14-TODAY()<=2,"Due ≤2d","Open")))) | V14: =IF(AND(G14<>"",M14="Yes",P14="",O14<>"Closed",O14<>"No Action Required",O14<>"Responded"),ROW(),"")
A15: EML-011 | Q15: =IF(OR(B15="",P15=""),"",P15-B15) | R15: =IF(OR(M15<>"Yes",P15<>"",O15="Closed",O15="No Action Required"),"",IF(N15="","Due date missing",IF(N15<TODAY(),"OVERDUE",IF(N15-TODAY()<=2,"Due ≤2d","Open")))) | V15: =IF(AND(G15<>"",M15="Yes",P15="",O15<>"Closed",O15<>"No Action Required",O15<>"Responded"),ROW(),"")
A16: EML-012 | Q16: =IF(OR(B16="",P16=""),"",P16-B16) | R16: =IF(OR(M16<>"Yes",P16<>"",O16="Closed",O16="No Action Required"),"",IF(N16="","Due date missing",IF(N16<TODAY(),"OVERDUE",IF(N16-TODAY()<=2,"Due ≤2d","Open")))) | V16: =IF(AND(G16<>"",M16="Yes",P16="",O16<>"Closed",O16<>"No Action Required",O16<>"Responded"),ROW(),"")
A17: EML-013 | Q17: =IF(OR(B17="",P17=""),"",P17-B17) | R17: =IF(OR(M17<>"Yes",P17<>"",O17="Closed",O17="No Action Required"),"",IF(N17="","Due date missing",IF(N17<TODAY(),"OVERDUE",IF(N17-TODAY()<=2,"Due ≤2d","Open")))) | V17: =IF(AND(G17<>"",M17="Yes",P17="",O17<>"Closed",O17<>"No Action Required",O17<>"Responded"),ROW(),"")
... A304: EML-300 | Q304: =IF(OR(B304="",P304=""),"",P304-B304) | R304: =IF(OR(M304<>"Yes",P304<>"",O304="Closed",O304="No Action Required"),"",IF(N304="","Due date missing",IF(N304<TODAY(),"OVERDUE",IF(N304-TODAY()<=2,"Due ≤2d","Open")))) | V304: =IF(AND(G304<>"",M304="Yes",P304="",O304<>"Closed",O304<>"No Action Required",O304<>"Responded"),ROW(),"")

Sheet Tasks
A1: Task & Action Tracker
A2: All actions arising from meetings, emails, findings and goals — ownership, progress notes, dependencies and next-week planning.
A3: White cells = your input | Grey cells = automatic (do not overwrite) | Row 5 is an illustrative example (italic) — overwrite or delete it.
A4: Task ID | B4: Date Raised | C4: Source | D4: Source Ref ID | E4: Workstream | F4: Task Description | G4: Linked Goal ID | H4: Owner | I4: Owner LoD | J4: Priority | K4: Status | L4: Start Date | M4: Due Date | N4: Completion Date | O4: % Complete | P4: Planned for Next Week? | Q4: Last Update Date | R4: Latest Update / Progress Note | S4: Dependency On (Person / Team) | T4: Needed By | U4: Blocker / Dependency Detail | V4: Evidence of Closure | W4: Days Open | X4: Due Flag | Y4: Notes | Z4: WR helper: completed | AA4: WR helper: moved forward | AB4: WR helper: current | AC4: WR helper: blocker | AD4: WR helper: next week
A5: TSK-001 | B5: 46310 | C5: Meeting | D5: MTG-001 | E5: Attribution & Ownership | F5: Reconcile EASM-discovered assets against CMDB extract; quantify unattributed / unknown assets by legal entity | G5: GOL-001 | H5: Me (2LoD CRI) | I5: 2LoD | J5: High | K5: In Progress | L5: 46311 | M5: 46332 | O5: 0.25 | P5: Yes | Q5: 46314 | R5: CMDB extract received for 2 of 3 entities; reconciliation of Entity A complete (41 unmapped hosts) | S5: Network Security (1LoD) | T5: 46318 | U5: CMDB extract for acquired Entity C outstanding (EML-001) | W5: =IF(B5="","",IF(N5<>"",N5-B5,TODAY()-B5)) -> 5 | X5: =IF(OR(M5="",K5="Completed",K5="Cancelled"),"",IF(M5<TODAY(),"OVERDUE",IF(M5-TODAY()<=7,"Due ≤7d","On Schedule"))) -> On Schedule | Z5: =IF(AND(N5<>"",N5>='Weekly Report'!$F$4,N5<='Weekly Report'!$F$5),ROW(),"") | AA5: =IF(AND(AND(Q5<>"",Q5>='Weekly Report'!$F$4,Q5<='Weekly Report'!$F$5),AND(F5<>"",K5<>"Completed",K5<>"Cancelled")),ROW(),"") -> 5 | AB5: =IF(AND(F5<>"",K5="In Progress"),ROW(),"") -> 5 | AC5: =IF(AND(AND(F5<>"",K5<>"Completed",K5<>"Cancelled"),OR(K5="Blocked",S5<>"")),ROW(),"") -> 5 | AD5: =IF(AND(AND(F5<>"",K5<>"Completed",K5<>"Cancelled"),OR(P5="Yes",AND(M5<>"",M5<='Weekly Report'!$F$7),AND(L5<>"",L5>='Weekly Report'!$F$6,L5<='Weekly Report'!$F$7))),ROW(),"") -> 5
A6: TSK-002 | W6: =IF(B6="","",IF(N6<>"",N6-B6,TODAY()-B6)) | X6: =IF(OR(M6="",K6="Completed",K6="Cancelled"),"",IF(M6<TODAY(),"OVERDUE",IF(M6-TODAY()<=7,"Due ≤7d","On Schedule"))) | Z6: =IF(AND(N6<>"",N6>='Weekly Report'!$F$4,N6<='Weekly Report'!$F$5),ROW(),"") | AA6: =IF(AND(AND(Q6<>"",Q6>='Weekly Report'!$F$4,Q6<='Weekly Report'!$F$5),AND(F6<>"",K6<>"Completed",K6<>"Cancelled")),ROW(),"") | AB6: =IF(AND(F6<>"",K6="In Progress"),ROW(),"") | AC6: =IF(AND(AND(F6<>"",K6<>"Completed",K6<>"Cancelled"),OR(K6="Blocked",S6<>"")),ROW(),"") | AD6: =IF(AND(AND(F6<>"",K6<>"Completed",K6<>"Cancelled"),OR(P6="Yes",AND(M6<>"",M6<='Weekly Report'!$F$7),AND(L6<>"",L6>='Weekly Report'!$F$6,L6<='Weekly Report'!$F$7))),ROW(),"")
A7: TSK-003 | W7: =IF(B7="","",IF(N7<>"",N7-B7,TODAY()-B7)) | X7: =IF(OR(M7="",K7="Completed",K7="Cancelled"),"",IF(M7<TODAY(),"OVERDUE",IF(M7-TODAY()<=7,"Due ≤7d","On Schedule"))) | Z7: =IF(AND(N7<>"",N7>='Weekly Report'!$F$4,N7<='Weekly Report'!$F$5),ROW(),"") | AA7: =IF(AND(AND(Q7<>"",Q7>='Weekly Report'!$F$4,Q7<='Weekly Report'!$F$5),AND(F7<>"",K7<>"Completed",K7<>"Cancelled")),ROW(),"") | AB7: =IF(AND(F7<>"",K7="In Progress"),ROW(),"") | AC7: =IF(AND(AND(F7<>"",K7<>"Completed",K7<>"Cancelled"),OR(K7="Blocked",S7<>"")),ROW(),"") | AD7: =IF(AND(AND(F7<>"",K7<>"Completed",K7<>"Cancelled"),OR(P7="Yes",AND(M7<>"",M7<='Weekly Report'!$F$7),AND(L7<>"",L7>='Weekly Report'!$F$6,L7<='Weekly Report'!$F$7))),ROW(),"")
A8: TSK-004 | W8: =IF(B8="","",IF(N8<>"",N8-B8,TODAY()-B8)) | X8: =IF(OR(M8="",K8="Completed",K8="Cancelled"),"",IF(M8<TODAY(),"OVERDUE",IF(M8-TODAY()<=7,"Due ≤7d","On Schedule"))) | Z8: =IF(AND(N8<>"",N8>='Weekly Report'!$F$4,N8<='Weekly Report'!$F$5),ROW(),"") | AA8: =IF(AND(AND(Q8<>"",Q8>='Weekly Report'!$F$4,Q8<='Weekly Report'!$F$5),AND(F8<>"",K8<>"Completed",K8<>"Cancelled")),ROW(),"") | AB8: =IF(AND(F8<>"",K8="In Progress"),ROW(),"") | AC8: =IF(AND(AND(F8<>"",K8<>"Completed",K8<>"Cancelled"),OR(K8="Blocked",S8<>"")),ROW(),"") | AD8: =IF(AND(AND(F8<>"",K8<>"Completed",K8<>"Cancelled"),OR(P8="Yes",AND(M8<>"",M8<='Weekly Report'!$F$7),AND(L8<>"",L8>='Weekly Report'!$F$6,L8<='Weekly Report'!$F$7))),ROW(),"")
A9: TSK-005 | W9: =IF(B9="","",IF(N9<>"",N9-B9,TODAY()-B9)) | X9: =IF(OR(M9="",K9="Completed",K9="Cancelled"),"",IF(M9<TODAY(),"OVERDUE",IF(M9-TODAY()<=7,"Due ≤7d","On Schedule"))) | Z9: =IF(AND(N9<>"",N9>='Weekly Report'!$F$4,N9<='Weekly Report'!$F$5),ROW(),"") | AA9: =IF(AND(AND(Q9<>"",Q9>='Weekly Report'!$F$4,Q9<='Weekly Report'!$F$5),AND(F9<>"",K9<>"Completed",K9<>"Cancelled")),ROW(),"") | AB9: =IF(AND(F9<>"",K9="In Progress"),ROW(),"") | AC9: =IF(AND(AND(F9<>"",K9<>"Completed",K9<>"Cancelled"),OR(K9="Blocked",S9<>"")),ROW(),"") | AD9: =IF(AND(AND(F9<>"",K9<>"Completed",K9<>"Cancelled"),OR(P9="Yes",AND(M9<>"",M9<='Weekly Report'!$F$7),AND(L9<>"",L9>='Weekly Report'!$F$6,L9<='Weekly Report'!$F$7))),ROW(),"")
A10: TSK-006 | W10: =IF(B10="","",IF(N10<>"",N10-B10,TODAY()-B10)) | X10: =IF(OR(M10="",K10="Completed",K10="Cancelled"),"",IF(M10<TODAY(),"OVERDUE",IF(M10-TODAY()<=7,"Due ≤7d","On Schedule"))) | Z10: =IF(AND(N10<>"",N10>='Weekly Report'!$F$4,N10<='Weekly Report'!$F$5),ROW(),"") | AA10: =IF(AND(AND(Q10<>"",Q10>='Weekly Report'!$F$4,Q10<='Weekly Report'!$F$5),AND(F10<>"",K10<>"Completed",K10<>"Cancelled")),ROW(),"") | AB10: =IF(AND(F10<>"",K10="In Progress"),ROW(),"") | AC10: =IF(AND(AND(F10<>"",K10<>"Completed",K10<>"Cancelled"),OR(K10="Blocked",S10<>"")),ROW(),"") | AD10: =IF(AND(AND(F10<>"",K10<>"Completed",K10<>"Cancelled"),OR(P10="Yes",AND(M10<>"",M10<='Weekly Report'!$F$7),AND(L10<>"",L10>='Weekly Report'!$F$6,L10<='Weekly Report'!$F$7))),ROW(),"")
A11: TSK-007 | W11: =IF(B11="","",IF(N11<>"",N11-B11,TODAY()-B11)) | X11: =IF(OR(M11="",K11="Completed",K11="Cancelled"),"",IF(M11<TODAY(),"OVERDUE",IF(M11-TODAY()<=7,"Due ≤7d","On Schedule"))) | Z11: =IF(AND(N11<>"",N11>='Weekly Report'!$F$4,N11<='Weekly Report'!$F$5),ROW(),"") | AA11: =IF(AND(AND(Q11<>"",Q11>='Weekly Report'!$F$4,Q11<='Weekly Report'!$F$5),AND(F11<>"",K11<>"Completed",K11<>"Cancelled")),ROW(),"") | AB11: =IF(AND(F11<>"",K11="In Progress"),ROW(),"") | AC11: =IF(AND(AND(F11<>"",K11<>"Completed",K11<>"Cancelled"),OR(K11="Blocked",S11<>"")),ROW(),"") | AD11: =IF(AND(AND(F11<>"",K11<>"Completed",K11<>"Cancelled"),OR(P11="Yes",AND(M11<>"",M11<='Weekly Report'!$F$7),AND(L11<>"",L11>='Weekly Report'!$F$6,L11<='Weekly Report'!$F$7))),ROW(),"")
A12: TSK-008 | W12: =IF(B12="","",IF(N12<>"",N12-B12,TODAY()-B12)) | X12: =IF(OR(M12="",K12="Completed",K12="Cancelled"),"",IF(M12<TODAY(),"OVERDUE",IF(M12-TODAY()<=7,"Due ≤7d","On Schedule"))) | Z12: =IF(AND(N12<>"",N12>='Weekly Report'!$F$4,N12<='Weekly Report'!$F$5),ROW(),"") | AA12: =IF(AND(AND(Q12<>"",Q12>='Weekly Report'!$F$4,Q12<='Weekly Report'!$F$5),AND(F12<>"",K12<>"Completed",K12<>"Cancelled")),ROW(),"") | AB12: =IF(AND(F12<>"",K12="In Progress"),ROW(),"") | AC12: =IF(AND(AND(F12<>"",K12<>"Completed",K12<>"Cancelled"),OR(K12="Blocked",S12<>"")),ROW(),"") | AD12: =IF(AND(AND(F12<>"",K12<>"Completed",K12<>"Cancelled"),OR(P12="Yes",AND(M12<>"",M12<='Weekly Report'!$F$7),AND(L12<>"",L12>='Weekly Report'!$F$6,L12<='Weekly Report'!$F$7))),ROW(),"")
A13: TSK-009 | W13: =IF(B13="","",IF(N13<>"",N13-B13,TODAY()-B13)) | X13: =IF(OR(M13="",K13="Completed",K13="Cancelled"),"",IF(M13<TODAY(),"OVERDUE",IF(M13-TODAY()<=7,"Due ≤7d","On Schedule"))) | Z13: =IF(AND(N13<>"",N13>='Weekly Report'!$F$4,N13<='Weekly Report'!$F$5),ROW(),"") | AA13: =IF(AND(AND(Q13<>"",Q13>='Weekly Report'!$F$4,Q13<='Weekly Report'!$F$5),AND(F13<>"",K13<>"Completed",K13<>"Cancelled")),ROW(),"") | AB13: =IF(AND(F13<>"",K13="In Progress"),ROW(),"") | AC13: =IF(AND(AND(F13<>"",K13<>"Completed",K13<>"Cancelled"),OR(K13="Blocked",S13<>"")),ROW(),"") | AD13: =IF(AND(AND(F13<>"",K13<>"Completed",K13<>"Cancelled"),OR(P13="Yes",AND(M13<>"",M13<='Weekly Report'!$F$7),AND(L13<>"",L13>='Weekly Report'!$F$6,L13<='Weekly Report'!$F$7))),ROW(),"")
