Workbook

Sheet Weekly Report
A1: EASM Mission – Weekly Status Report
A2: =Timeline!B4 -> EASM Assessment – 2LoD Cyber Risk Intelligence
B4: Meeting date | C4: =TODAY() -> 46315 | E4: Reporting period | F4: =TEXT(C5+1,"dd-mmm")&" to "&TEXT(C4,"dd-mmm-yyyy") -> 14-Oct to 20-Oct-2026
B5: Prev. meeting | C5: =C4-7 -> 46308 | E5: Next-week window | F5: =TEXT(C4+1,"dd-mmm")&" to "&TEXT(C4+7,"dd-mmm-yyyy") -> 21-Oct to 27-Oct-2026
B6: Edit only the two boxed dates. Everything below fills in automatically from the other tabs.
A8: 1 | B8: Overall Timeline
A9: # | B9: Week | C9: Mission period | D9: Day | E9: % time elapsed | F9: Current phase | G9: Plan check
B10: =IF(OR(Timeline!B5="",C4=""),"","Week "&(INT((C4-Timeline!B5)/7)+1)) -> Week 3 | C10: =IF(OR(Timeline!B5="",Timeline!B6=""),"",TEXT(Timeline!B5,"dd-mmm-yyyy")&" → "&TEXT(Timeline!B6,"dd-mmm-yyyy")) -> 05-Oct-2026 → 29-Jan-2027 | D10: =IF(OR(Timeline!B5="",Timeline!B6=""),"",(C4-Timeline!B5+1)&" of "&(Timeline!B6-Timeline!B5+1)) -> 16 of 117 | E10: =IF(OR(Timeline!B5="",Timeline!B6="",Timeline!B6=Timeline!B5),"",MAX(0,MIN(1,(C4-Timeline!B5)/(Timeline!B6-Timeline!B5)))) -> 0.12931034 | F10: =IFERROR(INDEX(Timeline!$B$9:$B$11,MATCH("In Progress",Timeline!$G$9:$G$11,0)),IFERROR(INDEX(Timeline!$B$9:$B$11,MATCH("Delayed",Timeline!$G$9:$G$11,0)),"None in progress")) -> Kick-off & Alignment | G10: =IF(COUNTIF(Timeline!$K$9:$K$11,"Behind plan")>0,COUNTIF(Timeline!$K$9:$K$11,"Behind plan")&" phase(s) behind plan","On plan") -> On plan
A11: # | B11: Phase | C11: Phase name | D11: Planned start | E11: Planned end | F11: Status | G11: Actions completed
B12: =Timeline!A9 -> P1 | C12: =Timeline!B9 -> Kick-off & Alignment | D12: =IF(Timeline!C9="","",Timeline!C9) -> 46300 | E12: =IF(Timeline!D9="","",Timeline!D9) -> 46318 | F12: =IF(Timeline!K9="Behind plan","Behind plan",Timeline!G9) -> In Progress | G12: =Timeline!J9 -> 1
B13: =Timeline!A10 -> P2 | C13: =Timeline!B10 -> Assessment & Execution | D13: =IF(Timeline!C10="","",Timeline!C10) -> 46321 | E13: =IF(Timeline!D10="","",Timeline!D10) -> 46374 | F13: =IF(Timeline!K10="Behind plan","Behind plan",Timeline!G10) -> Not Started | G13: =Timeline!J10 -> 0
B14: =Timeline!A11 -> P3 | C14: =Timeline!B11 -> Reporting & Conclusion | D14: =IF(Timeline!C11="","",Timeline!C11) -> 46391 | E14: =IF(Timeline!D11="","",Timeline!D11) -> 46416 | F14: =IF(Timeline!K11="Behind plan","Behind plan",Timeline!G11) -> Not Started | G14: =Timeline!J11 -> 0
A16: 2 | B16: Overall Status
A17: # | B17: RAG | C17: Why (one sentence)
B18: =IFERROR(INDEX('Weekly Status'!$B$5:$B$204,MATCH(MAX('Weekly Status'!$E$5:$E$204),'Weekly Status'!$E$5:$E$204,0)),"Not set") -> Amber | C18: =IFERROR(IF(INDEX('Weekly Status'!$C$5:$C$204,MATCH(MAX('Weekly Status'!$E$5:$E$204),'Weekly Status'!$E$5:$E$204,0))="","Add the one-sentence reason in the Weekly Status tab.",INDEX('Weekly Status'!$C$5:$C$204,MATCH(MAX('Weekly Status'!$E$5:$E$204),'Weekly Status'!$E$5:$E$204,0))),"Enter this week's RAG and one-sentence reason in the Weekly Status tab (date within the reporting period).") -> Kick-off completed on time, but the inventory audit is held back by the missing EASM procedure and a pending scope decision.
A19: # | B19: Suggested RAG | C19: Overdue actions | D19: Blocked actions | E19: Open escalations | F19: Phases behind plan | G19: Meetings / emails this period
B20: =IF(OR(COUNTIF(Timeline!$K$9:$K$11,"Behind plan")>0,COUNTIF(Actions!$P$5:$P$204,"Overdue")>=3),"Red",IF(OR(COUNTIF(Actions!$P$5:$P$204,"Overdue")>0,COUNTIF(Actions!$I$5:$I$204,"Blocked")>0,COUNTIFS(Escalations!$D$5:$D$204,"<>",Escalations!$I$5:$I$204,"Open")>0),"Amber","Green")) -> Amber | C20: =COUNTIF(Actions!$P$5:$P$204,"Overdue") -> 0 | D20: =COUNTIF(Actions!$I$5:$I$204,"Blocked") -> 1 | E20: =COUNTIFS(Escalations!$D$5:$D$204,"<>",Escalations!$I$5:$I$204,"Open") -> 1 | F20: =COUNTIF(Timeline!$K$9:$K$11,"Behind plan") -> 0 | G20: ="Meetings: "&COUNTIFS('Meetings & Emails'!$C$5:$C$204,"Meeting",'Meetings & Emails'!$B$5:$B$204,">"&'Weekly Report'!$C$5,'Meetings & Emails'!$B$5:$B$204,"<="&'Weekly Report'!$C$4)&" | Emails: "&COUNTIFS('Meetings & Emails'!$C$5:$C$204,"Email",'Meetings & Emails'!$B$5:$B$204,">"&'Weekly Report'!$C$5,'Meetings & Emails'!$B$5:$B$204,"<="&'Weekly Report'!$C$4) -> Meetings: 1 | Emails: 0
A22: 3 | B22: Progress Since Last Week | G22: =IF(COUNT(Actions!$Q$5:$Q$204)=0,"",IF(COUNT(Actions!$Q$5:$Q$204)>8,"Showing 8 of "&COUNT(Actions!$Q$5:$Q$204)&" – see Actions tab",COUNT(Actions!$Q$5:$Q$204)&" item(s)")) -> 2 item(s)
A23: # | B23: ID | C23: Action | D23: Owner | E23: Status | F23: Focus area | G23: Progress note
A24: =IF(B24="","",1) -> 1 | B24: =IFERROR(IF(INDEX(Actions!$A$5:$A$204,MATCH(1,Actions!$Q$5:$Q$204,0))="","",INDEX(Actions!$A$5:$A$204,MATCH(1,Actions!$Q$5:$Q$204,0))),"") -> ACT-001 | C24: =IFERROR(IF(INDEX(Actions!$C$5:$C$204,MATCH(1,Actions!$Q$5:$Q$204,0))="","",INDEX(Actions!$C$5:$C$204,MATCH(1,Actions!$Q$5:$Q$204,0))),"Nothing to report this period") -> Kick-off meeting with CISO Office and Network Security; agree scope and data requests | D24: =IFERROR(IF(INDEX(Actions!$F$5:$F$204,MATCH(1,Actions!$Q$5:$Q$204,0))="","",INDEX(Actions!$F$5:$F$204,MATCH(1,Actions!$Q$5:$Q$204,0))),"") -> Me | E24: =IFERROR(IF(INDEX(Actions!$I$5:$I$204,MATCH(1,Actions!$Q$5:$Q$204,0))="","",INDEX(Actions!$I$5:$I$204,MATCH(1,Actions!$Q$5:$Q$204,0))),"") -> Completed | F24: =IFERROR(IF(INDEX(Actions!$E$5:$E$204,MATCH(1,Actions!$Q$5:$Q$204,0))="","",INDEX(Actions!$E$5:$E$204,MATCH(1,Actions!$Q$5:$Q$204,0))),"") -> Governance | G24: =IFERROR(IF(INDEX(Actions!$L$5:$L$204,MATCH(1,Actions!$Q$5:$Q$204,0))="","",INDEX(Actions!$L$5:$L$204,MATCH(1,Actions!$Q$5:$Q$204,0))),"") -> Scope agreed: 3 legal entities, root domains and public IP ranges
A25: =IF(B25="","",2) -> 2 | B25: =IFERROR(IF(INDEX(Actions!$A$5:$A$204,MATCH(2,Actions!$Q$5:$Q$204,0))="","",INDEX(Actions!$A$5:$A$204,MATCH(2,Actions!$Q$5:$Q$204,0))),"") -> ACT-002 | C25: =IFERROR(IF(INDEX(Actions!$C$5:$C$204,MATCH(2,Actions!$Q$5:$Q$204,0))="","",INDEX(Actions!$C$5:$C$204,MATCH(2,Actions!$Q$5:$Q$204,0))),"") -> Reconcile EASM-discovered assets against CMDB extract | D25: =IFERROR(IF(INDEX(Actions!$F$5:$F$204,MATCH(2,Actions!$Q$5:$Q$204,0))="","",INDEX(Actions!$F$5:$F$204,MATCH(2,Actions!$Q$5:$Q$204,0))),"") -> Me | E25: =IFERROR(IF(INDEX(Actions!$I$5:$I$204,MATCH(2,Actions!$Q$5:$Q$204,0))="","",INDEX(Actions!$I$5:$I$204,MATCH(2,Actions!$Q$5:$Q$204,0))),"") -> In Progress | F25: =IFERROR(IF(INDEX(Actions!$E$5:$E$204,MATCH(2,Actions!$Q$5:$Q$204,0))="","",INDEX(Actions!$E$5:$E$204,MATCH(2,Actions!$Q$5:$Q$204,0))),"") -> Visibility | G25: =IFERROR(IF(INDEX(Actions!$L$5:$L$204,MATCH(2,Actions!$Q$5:$Q$204,0))="","",INDEX(Actions!$L$5:$L$204,MATCH(2,Actions!$Q$5:$Q$204,0))),"") -> First pass done: ~18% of discovered hosts not in CMDB
A26: =IF(B26="","",3) | B26: =IFERROR(IF(INDEX(Actions!$A$5:$A$204,MATCH(3,Actions!$Q$5:$Q$204,0))="","",INDEX(Actions!$A$5:$A$204,MATCH(3,Actions!$Q$5:$Q$204,0))),"") | C26: =IFERROR(IF(INDEX(Actions!$C$5:$C$204,MATCH(3,Actions!$Q$5:$Q$204,0))="","",INDEX(Actions!$C$5:$C$204,MATCH(3,Actions!$Q$5:$Q$204,0))),"") | D26: =IFERROR(IF(INDEX(Actions!$F$5:$F$204,MATCH(3,Actions!$Q$5:$Q$204,0))="","",INDEX(Actions!$F$5:$F$204,MATCH(3,Actions!$Q$5:$Q$204,0))),"") | E26: =IFERROR(IF(INDEX(Actions!$I$5:$I$204,MATCH(3,Actions!$Q$5:$Q$204,0))="","",INDEX(Actions!$I$5:$I$204,MATCH(3,Actions!$Q$5:$Q$204,0))),"") | F26: =IFERROR(IF(INDEX(Actions!$E$5:$E$204,MATCH(3,Actions!$Q$5:$Q$204,0))="","",INDEX(Actions!$E$5:$E$204,MATCH(3,Actions!$Q$5:$Q$204,0))),"") | G26: =IFERROR(IF(INDEX(Actions!$L$5:$L$204,MATCH(3,Actions!$Q$5:$Q$204,0))="","",INDEX(Actions!$L$5:$L$204,MATCH(3,Actions!$Q$5:$Q$204,0))),"")
A27: =IF(B27="","",4) | B27: =IFERROR(IF(INDEX(Actions!$A$5:$A$204,MATCH(4,Actions!$Q$5:$Q$204,0))="","",INDEX(Actions!$A$5:$A$204,MATCH(4,Actions!$Q$5:$Q$204,0))),"") | C27: =IFERROR(IF(INDEX(Actions!$C$5:$C$204,MATCH(4,Actions!$Q$5:$Q$204,0))="","",INDEX(Actions!$C$5:$C$204,MATCH(4,Actions!$Q$5:$Q$204,0))),"") | D27: =IFERROR(IF(INDEX(Actions!$F$5:$F$204,MATCH(4,Actions!$Q$5:$Q$204,0))="","",INDEX(Actions!$F$5:$F$204,MATCH(4,Actions!$Q$5:$Q$204,0))),"") | E27: =IFERROR(IF(INDEX(Actions!$I$5:$I$204,MATCH(4,Actions!$Q$5:$Q$204,0))="","",INDEX(Actions!$I$5:$I$204,MATCH(4,Actions!$Q$5:$Q$204,0))),"") | F27: =IFERROR(IF(INDEX(Actions!$E$5:$E$204,MATCH(4,Actions!$Q$5:$Q$204,0))="","",INDEX(Actions!$E$5:$E$204,MATCH(4,Actions!$Q$5:$Q$204,0))),"") | G27: =IFERROR(IF(INDEX(Actions!$L$5:$L$204,MATCH(4,Actions!$Q$5:$Q$204,0))="","",INDEX(Actions!$L$5:$L$204,MATCH(4,Actions!$Q$5:$Q$204,0))),"")
A28: =IF(B28="","",5) | B28: =IFERROR(IF(INDEX(Actions!$A$5:$A$204,MATCH(5,Actions!$Q$5:$Q$204,0))="","",INDEX(Actions!$A$5:$A$204,MATCH(5,Actions!$Q$5:$Q$204,0))),"") | C28: =IFERROR(IF(INDEX(Actions!$C$5:$C$204,MATCH(5,Actions!$Q$5:$Q$204,0))="","",INDEX(Actions!$C$5:$C$204,MATCH(5,Actions!$Q$5:$Q$204,0))),"") | D28: =IFERROR(IF(INDEX(Actions!$F$5:$F$204,MATCH(5,Actions!$Q$5:$Q$204,0))="","",INDEX(Actions!$F$5:$F$204,MATCH(5,Actions!$Q$5:$Q$204,0))),"") | E28: =IFERROR(IF(INDEX(Actions!$I$5:$I$204,MATCH(5,Actions!$Q$5:$Q$204,0))="","",INDEX(Actions!$I$5:$I$204,MATCH(5,Actions!$Q$5:$Q$204,0))),"") | F28: =IFERROR(IF(INDEX(Actions!$E$5:$E$204,MATCH(5,Actions!$Q$5:$Q$204,0))="","",INDEX(Actions!$E$5:$E$204,MATCH(5,Actions!$Q$5:$Q$204,0))),"") | G28: =IFERROR(IF(INDEX(Actions!$L$5:$L$204,MATCH(5,Actions!$Q$5:$Q$204,0))="","",INDEX(Actions!$L$5:$L$204,MATCH(5,Actions!$Q$5:$Q$204,0))),"")
A29: =IF(B29="","",6) | B29: =IFERROR(IF(INDEX(Actions!$A$5:$A$204,MATCH(6,Actions!$Q$5:$Q$204,0))="","",INDEX(Actions!$A$5:$A$204,MATCH(6,Actions!$Q$5:$Q$204,0))),"") | C29: =IFERROR(IF(INDEX(Actions!$C$5:$C$204,MATCH(6,Actions!$Q$5:$Q$204,0))="","",INDEX(Actions!$C$5:$C$204,MATCH(6,Actions!$Q$5:$Q$204,0))),"") | D29: =IFERROR(IF(INDEX(Actions!$F$5:$F$204,MATCH(6,Actions!$Q$5:$Q$204,0))="","",INDEX(Actions!$F$5:$F$204,MATCH(6,Actions!$Q$5:$Q$204,0))),"") | E29: =IFERROR(IF(INDEX(Actions!$I$5:$I$204,MATCH(6,Actions!$Q$5:$Q$204,0))="","",INDEX(Actions!$I$5:$I$204,MATCH(6,Actions!$Q$5:$Q$204,0))),"") | F29: =IFERROR(IF(INDEX(Actions!$E$5:$E$204,MATCH(6,Actions!$Q$5:$Q$204,0))="","",INDEX(Actions!$E$5:$E$204,MATCH(6,Actions!$Q$5:$Q$204,0))),"") | G29: =IFERROR(IF(INDEX(Actions!$L$5:$L$204,MATCH(6,Actions!$Q$5:$Q$204,0))="","",INDEX(Actions!$L$5:$L$204,MATCH(6,Actions!$Q$5:$Q$204,0))),"")
A30: =IF(B30="","",7) | B30: =IFERROR(IF(INDEX(Actions!$A$5:$A$204,MATCH(7,Actions!$Q$5:$Q$204,0))="","",INDEX(Actions!$A$5:$A$204,MATCH(7,Actions!$Q$5:$Q$204,0))),"") | C30: =IFERROR(IF(INDEX(Actions!$C$5:$C$204,MATCH(7,Actions!$Q$5:$Q$204,0))="","",INDEX(Actions!$C$5:$C$204,MATCH(7,Actions!$Q$5:$Q$204,0))),"") | D30: =IFERROR(IF(INDEX(Actions!$F$5:$F$204,MATCH(7,Actions!$Q$5:$Q$204,0))="","",INDEX(Actions!$F$5:$F$204,MATCH(7,Actions!$Q$5:$Q$204,0))),"") | E30: =IFERROR(IF(INDEX(Actions!$I$5:$I$204,MATCH(7,Actions!$Q$5:$Q$204,0))="","",INDEX(Actions!$I$5:$I$204,MATCH(7,Actions!$Q$5:$Q$204,0))),"") | F30: =IFERROR(IF(INDEX(Actions!$E$5:$E$204,MATCH(7,Actions!$Q$5:$Q$204,0))="","",INDEX(Actions!$E$5:$E$204,MATCH(7,Actions!$Q$5:$Q$204,0))),"") | G30: =IFERROR(IF(INDEX(Actions!$L$5:$L$204,MATCH(7,Actions!$Q$5:$Q$204,0))="","",INDEX(Actions!$L$5:$L$204,MATCH(7,Actions!$Q$5:$Q$204,0))),"")
A31: =IF(B31="","",8) | B31: =IFERROR(IF(INDEX(Actions!$A$5:$A$204,MATCH(8,Actions!$Q$5:$Q$204,0))="","",INDEX(Actions!$A$5:$A$204,MATCH(8,Actions!$Q$5:$Q$204,0))),"") | C31: =IFERROR(IF(INDEX(Actions!$C$5:$C$204,MATCH(8,Actions!$Q$5:$Q$204,0))="","",INDEX(Actions!$C$5:$C$204,MATCH(8,Actions!$Q$5:$Q$204,0))),"") | D31: =IFERROR(IF(INDEX(Actions!$F$5:$F$204,MATCH(8,Actions!$Q$5:$Q$204,0))="","",INDEX(Actions!$F$5:$F$204,MATCH(8,Actions!$Q$5:$Q$204,0))),"") | E31: =IFERROR(IF(INDEX(Actions!$I$5:$I$204,MATCH(8,Actions!$Q$5:$Q$204,0))="","",INDEX(Actions!$I$5:$I$204,MATCH(8,Actions!$Q$5:$Q$204,0))),"") | F31: =IFERROR(IF(INDEX(Actions!$E$5:$E$204,MATCH(8,Actions!$Q$5:$Q$204,0))="","",INDEX(Actions!$E$5:$E$204,MATCH(8,Actions!$Q$5:$Q$204,0))),"") | G31: =IFERROR(IF(INDEX(Actions!$L$5:$L$204,MATCH(8,Actions!$Q$5:$Q$204,0))="","",INDEX(Actions!$L$5:$L$204,MATCH(8,Actions!$Q$5:$Q$204,0))),"")
A33: 4 | B33: Current Work | G33: =IF(COUNT(Actions!$R$5:$R$204)=0,"",IF(COUNT(Actions!$R$5:$R$204)>8,"Showing 8 of "&COUNT(Actions!$R$5:$R$204)&" – see Actions tab",COUNT(Actions!$R$5:$R$204)&" item(s)")) -> 1 item(s)
A34: # | B34: ID | C34: Action | D34: Owner | E34: Due date | F34: Focus area | G34: Progress note
A35: =IF(B35="","",1) -> 1 | B35: =IFERROR(IF(INDEX(Actions!$A$5:$A$204,MATCH(1,Actions!$R$5:$R$204,0))="","",INDEX(Actions!$A$5:$A$204,MATCH(1,Actions!$R$5:$R$204,0))),"") -> ACT-002 | C35: =IFERROR(IF(INDEX(Actions!$C$5:$C$204,MATCH(1,Actions!$R$5:$R$204,0))="","",INDEX(Actions!$C$5:$C$204,MATCH(1,Actions!$R$5:$R$204,0))),"Nothing to report this period") -> Reconcile EASM-discovered assets against CMDB extract | D35: =IFERROR(IF(INDEX(Actions!$F$5:$F$204,MATCH(1,Actions!$R$5:$R$204,0))="","",INDEX(Actions!$F$5:$F$204,MATCH(1,Actions!$R$5:$R$204,0))),"") -> Me | E35: =IFERROR(IF(INDEX(Actions!$H$5:$H$204,MATCH(1,Actions!$R$5:$R$204,0))="","",INDEX(Actions!$H$5:$H$204,MATCH(1,Actions!$R$5:$R$204,0))),"") -> 46332 | F35: =IFERROR(IF(INDEX(Actions!$E$5:$E$204,MATCH(1,Actions!$R$5:$R$204,0))="","",INDEX(Actions!$E$5:$E$204,MATCH(1,Actions!$R$5:$R$204,0))),"") -> Visibility | G35: =IFERROR(IF(INDEX(Actions!$L$5:$L$204,MATCH(1,Actions!$R$5:$R$204,0))="","",INDEX(Actions!$L$5:$L$204,MATCH(1,Actions!$R$5:$R$204,0))),"") -> First pass done: ~18% of discovered hosts not in CMDB
A36: =IF(B36="","",2) | B36: =IFERROR(IF(INDEX(Actions!$A$5:$A$204,MATCH(2,Actions!$R$5:$R$204,0))="","",INDEX(Actions!$A$5:$A$204,MATCH(2,Actions!$R$5:$R$204,0))),"") | C36: =IFERROR(IF(INDEX(Actions!$C$5:$C$204,MATCH(2,Actions!$R$5:$R$204,0))="","",INDEX(Actions!$C$5:$C$204,MATCH(2,Actions!$R$5:$R$204,0))),"") | D36: =IFERROR(IF(INDEX(Actions!$F$5:$F$204,MATCH(2,Actions!$R$5:$R$204,0))="","",INDEX(Actions!$F$5:$F$204,MATCH(2,Actions!$R$5:$R$204,0))),"") | E36: =IFERROR(IF(INDEX(Actions!$H$5:$H$204,MATCH(2,Actions!$R$5:$R$204,0))="","",INDEX(Actions!$H$5:$H$204,MATCH(2,Actions!$R$5:$R$204,0))),"") | F36: =IFERROR(IF(INDEX(Actions!$E$5:$E$204,MATCH(2,Actions!$R$5:$R$204,0))="","",INDEX(Actions!$E$5:$E$204,MATCH(2,Actions!$R$5:$R$204,0))),"") | G36: =IFERROR(IF(INDEX(Actions!$L$5:$L$204,MATCH(2,Actions!$R$5:$R$204,0))="","",INDEX(Actions!$L$5:$L$204,MATCH(2,Actions!$R$5:$R$204,0))),"")
A37: =IF(B37="","",3) | B37: =IFERROR(IF(INDEX(Actions!$A$5:$A$204,MATCH(3,Actions!$R$5:$R$204,0))="","",INDEX(Actions!$A$5:$A$204,MATCH(3,Actions!$R$5:$R$204,0))),"") | C37: =IFERROR(IF(INDEX(Actions!$C$5:$C$204,MATCH(3,Actions!$R$5:$R$204,0))="","",INDEX(Actions!$C$5:$C$204,MATCH(3,Actions!$R$5:$R$204,0))),"") | D37: =IFERROR(IF(INDEX(Actions!$F$5:$F$204,MATCH(3,Actions!$R$5:$R$204,0))="","",INDEX(Actions!$F$5:$F$204,MATCH(3,Actions!$R$5:$R$204,0))),"") | E37: =IFERROR(IF(INDEX(Actions!$H$5:$H$204,MATCH(3,Actions!$R$5:$R$204,0))="","",INDEX(Actions!$H$5:$H$204,MATCH(3,Actions!$R$5:$R$204,0))),"") | F37: =IFERROR(IF(INDEX(Actions!$E$5:$E$204,MATCH(3,Actions!$R$5:$R$204,0))="","",INDEX(Actions!$E$5:$E$204,MATCH(3,Actions!$R$5:$R$204,0))),"") | G37: =IFERROR(IF(INDEX(Actions!$L$5:$L$204,MATCH(3,Actions!$R$5:$R$204,0))="","",INDEX(Actions!$L$5:$L$204,MATCH(3,Actions!$R$5:$R$204,0))),"")
A38: =IF(B38="","",4) | B38: =IFERROR(IF(INDEX(Actions!$A$5:$A$204,MATCH(4,Actions!$R$5:$R$204,0))="","",INDEX(Actions!$A$5:$A$204,MATCH(4,Actions!$R$5:$R$204,0))),"") | C38: =IFERROR(IF(INDEX(Actions!$C$5:$C$204,MATCH(4,Actions!$R$5:$R$204,0))="","",INDEX(Actions!$C$5:$C$204,MATCH(4,Actions!$R$5:$R$204,0))),"") | D38: =IFERROR(IF(INDEX(Actions!$F$5:$F$204,MATCH(4,Actions!$R$5:$R$204,0))="","",INDEX(Actions!$F$5:$F$204,MATCH(4,Actions!$R$5:$R$204,0))),"") | E38: =IFERROR(IF(INDEX(Actions!$H$5:$H$204,MATCH(4,Actions!$R$5:$R$204,0))="","",INDEX(Actions!$H$5:$H$204,MATCH(4,Actions!$R$5:$R$204,0))),"") | F38: =IFERROR(IF(INDEX(Actions!$E$5:$E$204,MATCH(4,Actions!$R$5:$R$204,0))="","",INDEX(Actions!$E$5:$E$204,MATCH(4,Actions!$R$5:$R$204,0))),"") | G38: =IFERROR(IF(INDEX(Actions!$L$5:$L$204,MATCH(4,Actions!$R$5:$R$204,0))="","",INDEX(Actions!$L$5:$L$204,MATCH(4,Actions!$R$5:$R$204,0))),"")
A39: =IF(B39="","",5) | B39: =IFERROR(IF(INDEX(Actions!$A$5:$A$204,MATCH(5,Actions!$R$5:$R$204,0))="","",INDEX(Actions!$A$5:$A$204,MATCH(5,Actions!$R$5:$R$204,0))),"") | C39: =IFERROR(IF(INDEX(Actions!$C$5:$C$204,MATCH(5,Actions!$R$5:$R$204,0))="","",INDEX(Actions!$C$5:$C$204,MATCH(5,Actions!$R$5:$R$204,0))),"") | D39: =IFERROR(IF(INDEX(Actions!$F$5:$F$204,MATCH(5,Actions!$R$5:$R$204,0))="","",INDEX(Actions!$F$5:$F$204,MATCH(5,Actions!$R$5:$R$204,0))),"") | E39: =IFERROR(IF(INDEX(Actions!$H$5:$H$204,MATCH(5,Actions!$R$5:$R$204,0))="","",INDEX(Actions!$H$5:$H$204,MATCH(5,Actions!$R$5:$R$204,0))),"") | F39: =IFERROR(IF(INDEX(Actions!$E$5:$E$204,MATCH(5,Actions!$R$5:$R$204,0))="","",INDEX(Actions!$E$5:$E$204,MATCH(5,Actions!$R$5:$R$204,0))),"") | G39: =IFERROR(IF(INDEX(Actions!$L$5:$L$204,MATCH(5,Actions!$R$5:$R$204,0))="","",INDEX(Actions!$L$5:$L$204,MATCH(5,Actions!$R$5:$R$204,0))),"")
A40: =IF(B40="","",6) | B40: =IFERROR(IF(INDEX(Actions!$A$5:$A$204,MATCH(6,Actions!$R$5:$R$204,0))="","",INDEX(Actions!$A$5:$A$204,MATCH(6,Actions!$R$5:$R$204,0))),"") | C40: =IFERROR(IF(INDEX(Actions!$C$5:$C$204,MATCH(6,Actions!$R$5:$R$204,0))="","",INDEX(Actions!$C$5:$C$204,MATCH(6,Actions!$R$5:$R$204,0))),"") | D40: =IFERROR(IF(INDEX(Actions!$F$5:$F$204,MATCH(6,Actions!$R$5:$R$204,0))="","",INDEX(Actions!$F$5:$F$204,MATCH(6,Actions!$R$5:$R$204,0))),"") | E40: =IFERROR(IF(INDEX(Actions!$H$5:$H$204,MATCH(6,Actions!$R$5:$R$204,0))="","",INDEX(Actions!$H$5:$H$204,MATCH(6,Actions!$R$5:$R$204,0))),"") | F40: =IFERROR(IF(INDEX(Actions!$E$5:$E$204,MATCH(6,Actions!$R$5:$R$204,0))="","",INDEX(Actions!$E$5:$E$204,MATCH(6,Actions!$R$5:$R$204,0))),"") | G40: =IFERROR(IF(INDEX(Actions!$L$5:$L$204,MATCH(6,Actions!$R$5:$R$204,0))="","",INDEX(Actions!$L$5:$L$204,MATCH(6,Actions!$R$5:$R$204,0))),"")
A41: =IF(B41="","",7) | B41: =IFERROR(IF(INDEX(Actions!$A$5:$A$204,MATCH(7,Actions!$R$5:$R$204,0))="","",INDEX(Actions!$A$5:$A$204,MATCH(7,Actions!$R$5:$R$204,0))),"") | C41: =IFERROR(IF(INDEX(Actions!$C$5:$C$204,MATCH(7,Actions!$R$5:$R$204,0))="","",INDEX(Actions!$C$5:$C$204,MATCH(7,Actions!$R$5:$R$204,0))),"") | D41: =IFERROR(IF(INDEX(Actions!$F$5:$F$204,MATCH(7,Actions!$R$5:$R$204,0))="","",INDEX(Actions!$F$5:$F$204,MATCH(7,Actions!$R$5:$R$204,0))),"") | E41: =IFERROR(IF(INDEX(Actions!$H$5:$H$204,MATCH(7,Actions!$R$5:$R$204,0))="","",INDEX(Actions!$H$5:$H$204,MATCH(7,Actions!$R$5:$R$204,0))),"") | F41: =IFERROR(IF(INDEX(Actions!$E$5:$E$204,MATCH(7,Actions!$R$5:$R$204,0))="","",INDEX(Actions!$E$5:$E$204,MATCH(7,Actions!$R$5:$R$204,0))),"") | G41: =IFERROR(IF(INDEX(Actions!$L$5:$L$204,MATCH(7,Actions!$R$5:$R$204,0))="","",INDEX(Actions!$L$5:$L$204,MATCH(7,Actions!$R$5:$R$204,0))),"")
A42: =IF(B42="","",8) | B42: =IFERROR(IF(INDEX(Actions!$A$5:$A$204,MATCH(8,Actions!$R$5:$R$204,0))="","",INDEX(Actions!$A$5:$A$204,MATCH(8,Actions!$R$5:$R$204,0))),"") | C42: =IFERROR(IF(INDEX(Actions!$C$5:$C$204,MATCH(8,Actions!$R$5:$R$204,0))="","",INDEX(Actions!$C$5:$C$204,MATCH(8,Actions!$R$5:$R$204,0))),"") | D42: =IFERROR(IF(INDEX(Actions!$F$5:$F$204,MATCH(8,Actions!$R$5:$R$204,0))="","",INDEX(Actions!$F$5:$F$204,MATCH(8,Actions!$R$5:$R$204,0))),"") | E42: =IFERROR(IF(INDEX(Actions!$H$5:$H$204,MATCH(8,Actions!$R$5:$R$204,0))="","",INDEX(Actions!$H$5:$H$204,MATCH(8,Actions!$R$5:$R$204,0))),"") | F42: =IFERROR(IF(INDEX(Actions!$E$5:$E$204,MATCH(8,Actions!$R$5:$R$204,0))="","",INDEX(Actions!$E$5:$E$204,MATCH(8,Actions!$R$5:$R$204,0))),"") | G42: =IFERROR(IF(INDEX(Actions!$L$5:$L$204,MATCH(8,Actions!$R$5:$R$204,0))="","",INDEX(Actions!$L$5:$L$204,MATCH(8,Actions!$R$5:$R$204,0))),"")
A44: 5 | B44: Findings – New or Materially Changed | G44: =IF(COUNT(Findings!$O$5:$O$204)=0,"",IF(COUNT(Findings!$O$5:$O$204)>8,"Showing 8 of "&COUNT(Findings!$O$5:$O$204)&" – see Findings tab",COUNT(Findings!$O$5:$O$204)&" item(s)")) -> 1 item(s)
A45: # | B45: ID | C45: Finding | D45: Severity | E45: Remediation status | F45: New / Changed | G45: Update / remediation
A46: =IF(B46="","",1) -> 1 | B46: =IFERROR(IF(INDEX(Findings!$A$5:$A$204,MATCH(1,Findings!$O$5:$O$204,0))="","",INDEX(Findings!$A$5:$A$204,MATCH(1,Findings!$O$5:$O$204,0))),"") -> FND-001 | C46: =IFERROR(IF(INDEX(Findings!$E$5:$E$204,MATCH(1,Findings!$O$5:$O$204,0))="","",INDEX(Findings!$E$5:$E$204,MATCH(1,Findings!$O$5:$O$204,0))),"Nothing to report this period") -> ~18% of internet-facing hosts discovered by EASM are not recorded in the CMDB (mostly acquired entity B) | D46: =IFERROR(IF(INDEX(Findings!$G$5:$G$204,MATCH(1,Findings!$O$5:$O$204,0))="","",INDEX(Findings!$G$5:$G$204,MATCH(1,Findings!$O$5:$O$204,0))),"") -> High | E46: =IFERROR(IF(INDEX(Findings!$I$5:$I$204,MATCH(1,Findings!$O$5:$O$204,0))="","",INDEX(Findings!$I$5:$I$204,MATCH(1,Findings!$O$5:$O$204,0))),"") -> Open | F46: =IFERROR(IF(INDEX(Findings!$M$5:$M$204,MATCH(1,Findings!$O$5:$O$204,0))="","",INDEX(Findings!$M$5:$M$204,MATCH(1,Findings!$O$5:$O$204,0))),"") -> New | G46: =IFERROR(IF(INDEX(Findings!$L$5:$L$204,MATCH(1,Findings!$O$5:$O$204,0))="","",INDEX(Findings!$L$5:$L$204,MATCH(1,Findings!$O$5:$O$204,0))),"") -> New – root cause analysis requested from 1LoD
...

Sheet Weekly Status
A1: Weekly Status
A2: One row per weekly meeting: your overall RAG and the one-sentence reason. Builds a status history.
A3: White = you type | Grey = automatic | Italic rows = examples (overwrite or delete)
A4: Meeting Date | B4: Overall Status (RAG) | C4: Why (one sentence) | D4: Other Notes | E4: helper:wk
A5: 46315 | B5: Amber | C5: Kick-off completed on time, but the inventory audit is held back by the missing EASM procedure and a pending scope decision. | E5: =IF(AND(N(A5)>'Weekly Report'!$C$5,N(A5)<='Weekly Report'!$C$4),COUNT(E$4:E4)+1,"") -> 1
E6: =IF(AND(N(A6)>'Weekly Report'!$C$5,N(A6)<='Weekly Report'!$C$4),COUNT(E$4:E5)+1,"")
E7: =IF(AND(N(A7)>'Weekly Report'!$C$5,N(A7)<='Weekly Report'!$C$4),COUNT(E$4:E6)+1,"")
E8: =IF(AND(N(A8)>'Weekly Report'!$C$5,N(A8)<='Weekly Report'!$C$4),COUNT(E$4:E7)+1,"")
E9: =IF(AND(N(A9)>'Weekly Report'!$C$5,N(A9)<='Weekly Report'!$C$4),COUNT(E$4:E8)+1,"")
E10: =IF(AND(N(A10)>'Weekly Report'!$C$5,N(A10)<='Weekly Report'!$C$4),COUNT(E$4:E9)+1,"")
E11: =IF(AND(N(A11)>'Weekly Report'!$C$5,N(A11)<='Weekly Report'!$C$4),COUNT(E$4:E10)+1,"")
E12: =IF(AND(N(A12)>'Weekly Report'!$C$5,N(A12)<='Weekly Report'!$C$4),COUNT(E$4:E11)+1,"")
E13: =IF(AND(N(A13)>'Weekly Report'!$C$5,N(A13)<='Weekly Report'!$C$4),COUNT(E$4:E12)+1,"")
E14: =IF(AND(N(A14)>'Weekly Report'!$C$5,N(A14)<='Weekly Report'!$C$4),COUNT(E$4:E13)+1,"")
E15: =IF(AND(N(A15)>'Weekly Report'!$C$5,N(A15)<='Weekly Report'!$C$4),COUNT(E$4:E14)+1,"")
E16: =IF(AND(N(A16)>'Weekly Report'!$C$5,N(A16)<='Weekly Report'!$C$4),COUNT(E$4:E15)+1,"")
E17: =IF(AND(N(A17)>'Weekly Report'!$C$5,N(A17)<='Weekly Report'!$C$4),COUNT(E$4:E16)+1,"")
... E204: =IF(AND(N(A204)>'Weekly Report'!$C$5,N(A204)<='Weekly Report'!$C$4),COUNT(E$4:E203)+1,"")

Sheet Timeline
A1: Timeline
A2: Mission dates, the 3 phases and coverage of methods × focus areas.
A3: White = you type | Grey = automatic | Italic rows = examples (overwrite or delete)
A4: Mission name | B4: EASM Assessment – 2LoD Cyber Risk Intelligence
A5: Mission start | B5: 46300
A6: Mission end | B6: 46416
A8: # | B8: Phase | C8: Planned Start | D8: Planned End | E8: Actual Start | F8: Actual End | G8: Status | H8: Actions | I8: Completed | J8: % Complete | K8: Plan Check | L8: Comment
A9: P1 | B9: Kick-off & Alignment | C9: 46300 | D9: 46318 | E9: 46300 | G9: In Progress | H9: =COUNTIFS(Actions!$C$5:$C$204,"<>",Actions!$B$5:$B$204,B9,Actions!$I$5:$I$204,"<>Cancelled") -> 1 | I9: =COUNTIFS(Actions!$C$5:$C$204,"<>",Actions!$B$5:$B$204,B9,Actions!$I$5:$I$204,"Completed") -> 1 | J9: =IF(H9=0,0,I9/H9) -> 1 | K9: =IF(G9="Completed","Done",IF(D9="","",IF(D9<'Weekly Report'!$C$4,"Behind plan",IF(AND(C9<>"",C9<='Weekly Report'!$C$4,G9="Not Started"),"Late start","On plan")))) -> On plan
A10: P2 | B10: Assessment & Execution | C10: 46321 | D10: 46374 | G10: Not Started | H10: =COUNTIFS(Actions!$C$5:$C$204,"<>",Actions!$B$5:$B$204,B10,Actions!$I$5:$I$204,"<>Cancelled") -> 2 | I10: =COUNTIFS(Actions!$C$5:$C$204,"<>",Actions!$B$5:$B$204,B10,Actions!$I$5:$I$204,"Completed") -> 0 | J10: =IF(H10=0,0,I10/H10) -> 0 | K10: =IF(G10="Completed","Done",IF(D10="","",IF(D10<'Weekly Report'!$C$4,"Behind plan",IF(AND(C10<>"",C10<='Weekly Report'!$C$4,G10="Not Started"),"Late start","On plan")))) -> On plan
A11: P3 | B11: Reporting & Conclusion | C11: 46391 | D11: 46416 | G11: Not Started | H11: =COUNTIFS(Actions!$C$5:$C$204,"<>",Actions!$B$5:$B$204,B11,Actions!$I$5:$I$204,"<>Cancelled") -> 0 | I11: =COUNTIFS(Actions!$C$5:$C$204,"<>",Actions!$B$5:$B$204,B11,Actions!$I$5:$I$204,"Completed") -> 0 | J11: =IF(H11=0,0,I11/H11) -> 0 | K11: =IF(G11="Completed","Done",IF(D11="","",IF(D11<'Weekly Report'!$C$4,"Behind plan",IF(AND(C11<>"",C11<='Weekly Report'!$C$4,G11="Not Started"),"Late start","On plan")))) -> On plan
A14: Coverage – number of actions per focus area and method (cancelled excluded)
A15: Focus Area | B15: Document Review | C15: Stakeholder Engagement | D15: Inventory Audit | E15: Completeness Validation | F15: Total Actions | G15: Open Findings
A16: Visibility | B16: =COUNTIFS(Actions!$C$5:$C$204,"<>",Actions!$E$5:$E$204,$A16,Actions!$D$5:$D$204,B$15,Actions!$I$5:$I$204,"<>Cancelled") -> 0 | C16: =COUNTIFS(Actions!$C$5:$C$204,"<>",Actions!$E$5:$E$204,$A16,Actions!$D$5:$D$204,C$15,Actions!$I$5:$I$204,"<>Cancelled") -> 0 | D16: =COUNTIFS(Actions!$C$5:$C$204,"<>",Actions!$E$5:$E$204,$A16,Actions!$D$5:$D$204,D$15,Actions!$I$5:$I$204,"<>Cancelled") -> 1 | E16: =COUNTIFS(Actions!$C$5:$C$204,"<>",Actions!$E$5:$E$204,$A16,Actions!$D$5:$D$204,E$15,Actions!$I$5:$I$204,"<>Cancelled") -> 0 | F16: =COUNTIFS(Actions!$C$5:$C$204,"<>",Actions!$E$5:$E$204,$A16,Actions!$I$5:$I$204,"<>Cancelled") -> 1 | G16: =COUNTIFS(Findings!$E$5:$E$204,"<>",Findings!$C$5:$C$204,$A16,Findings!$I$5:$I$204,"<>Remediated",Findings!$I$5:$I$204,"<>Closed",Findings!$I$5:$I$204,"<>Risk Accepted") -> 1
A17: Governance | B17: =COUNTIFS(Actions!$C$5:$C$204,"<>",Actions!$E$5:$E$204,$A17,Actions!$D$5:$D$204,B$15,Actions!$I$5:$I$204,"<>Cancelled") -> 1 | C17: =COUNTIFS(Actions!$C$5:$C$204,"<>",Actions!$E$5:$E$204,$A17,Actions!$D$5:$D$204,C$15,Actions!$I$5:$I$204,"<>Cancelled") -> 1 | D17: =COUNTIFS(Actions!$C$5:$C$204,"<>",Actions!$E$5:$E$204,$A17,Actions!$D$5:$D$204,D$15,Actions!$I$5:$I$204,"<>Cancelled") -> 0 | E17: =COUNTIFS(Actions!$C$5:$C$204,"<>",Actions!$E$5:$E$204,$A17,Actions!$D$5:$D$204,E$15,Actions!$I$5:$I$204,"<>Cancelled") -> 0 | F17: =COUNTIFS(Actions!$C$5:$C$204,"<>",Actions!$E$5:$E$204,$A17,Actions!$I$5:$I$204,"<>Cancelled") -> 2 | G17: =COUNTIFS(Findings!$E$5:$E$204,"<>",Findings!$C$5:$C$204,$A17,Findings!$I$5:$I$204,"<>Remediated",Findings!$I$5:$I$204,"<>Closed",Findings!$I$5:$I$204,"<>Risk Accepted") -> 0
A18: Integration | B18: =COUNTIFS(Actions!$C$5:$C$204,"<>",Actions!$E$5:$E$204,$A18,Actions!$D$5:$D$204,B$15,Actions!$I$5:$I$204,"<>Cancelled") -> 0 | C18: =COUNTIFS(Actions!$C$5:$C$204,"<>",Actions!$E$5:$E$204,$A18,Actions!$D$5:$D$204,C$15,Actions!$I$5:$I$204,"<>Cancelled") -> 0 | D18: =COUNTIFS(Actions!$C$5:$C$204,"<>",Actions!$E$5:$E$204,$A18,Actions!$D$5:$D$204,D$15,Actions!$I$5:$I$204,"<>Cancelled") -> 0 | E18: =COUNTIFS(Actions!$C$5:$C$204,"<>",Actions!$E$5:$E$204,$A18,Actions!$D$5:$D$204,E$15,Actions!$I$5:$I$204,"<>Cancelled") -> 0 | F18: =COUNTIFS(Actions!$C$5:$C$204,"<>",Actions!$E$5:$E$204,$A18,Actions!$I$5:$I$204,"<>Cancelled") -> 0 | G18: =COUNTIFS(Findings!$E$5:$E$204,"<>",Findings!$C$5:$C$204,$A18,Findings!$I$5:$I$204,"<>Remediated",Findings!$I$5:$I$204,"<>Closed",Findings!$I$5:$I$204,"<>Risk Accepted") -> 0
A19: Sustainability | B19: =COUNTIFS(Actions!$C$5:$C$204,"<>",Actions!$E$5:$E$204,$A19,Actions!$D$5:$D$204,B$15,Actions!$I$5:$I$204,"<>Cancelled") -> 0 | C19: =COUNTIFS(Actions!$C$5:$C$204,"<>",Actions!$E$5:$E$204,$A19,Actions!$D$5:$D$204,C$15,Actions!$I$5:$I$204,"<>Cancelled") -> 0 | D19: =COUNTIFS(Actions!$C$5:$C$204,"<>",Actions!$E$5:$E$204,$A19,Actions!$D$5:$D$204,D$15,Actions!$I$5:$I$204,"<>Cancelled") -> 0 | E19: =COUNTIFS(Actions!$C$5:$C$204,"<>",Actions!$E$5:$E$204,$A19,Actions!$D$5:$D$204,E$15,Actions!$I$5:$I$204,"<>Cancelled") -> 0 | F19: =COUNTIFS(Actions!$C$5:$C$204,"<>",Actions!$E$5:$E$204,$A19,Actions!$I$5:$I$204,"<>Cancelled") -> 0 | G19: =COUNTIFS(Findings!$E$5:$E$204,"<>",Findings!$C$5:$C$204,$A19,Findings!$I$5:$I$204,"<>Remediated",Findings!$I$5:$I$204,"<>Closed",Findings!$I$5:$I$204,"<>Risk Accepted") -> 0
A21: Amber cell = no action yet for that focus area / method combination (possible coverage gap).

Sheet Actions
A1: Actions
A2: Every task of the mission. Update Status, Last Updated and Progress Note before each weekly meeting.
A3: White = you type | Grey = automatic | Italic rows = examples (overwrite or delete)
A4: ID | B4: Phase | C4: Action / Task | D4: Method | E4: Focus Area | F4: Owner | G4: Start Date | H4: Due Date | I4: Status | J4: Completed Date | K4: Last Updated | L4: Progress Note (latest) | M4: Blocker / Dependency | N4: Waiting On (who) | O4: Plan for Next Week? | P4: Overdue? | Q4: helper:prog | R4: helper:curr | S4: helper:blk | T4: helper:next
A5: ACT-001 | B5: Kick-off & Alignment | C5: Kick-off meeting with CISO Office and Network Security; agree scope and data requests | D5: Stakeholder Engagement | E5: Governance | F5: Me | G5: 46300 | H5: 46311 | I5: Completed | J5: 46310 | K5: 46310 | L5: Scope agreed: 3 legal entities, root domains and public IP ranges | O5: No | P5: =IF(OR(C5="",H5="",I5="Completed",I5="Cancelled"),"",IF(H5<TODAY(),"Overdue","")) | Q5: =IF(AND(C5<>"",I5<>"Cancelled",OR(AND(N(J5)>'Weekly Report'!$C$5,N(J5)<='Weekly Report'!$C$4),AND(N(K5)>'Weekly Report'!$C$5,N(K5)<='Weekly Report'!$C$4))),COUNT(Q$4:Q4)+1,"") -> 1 | R5: =IF(AND(C5<>"",I5="In Progress"),COUNT(R$4:R4)+1,"") | S5: =IF(AND(C5<>"",I5<>"Completed",I5<>"Cancelled",OR(I5="Blocked",M5<>"")),COUNT(S$4:S4)+1,"") | T5: =IF(AND(C5<>"",I5<>"Completed",I5<>"Cancelled",OR(O5="Yes",AND(N(H5)>'Weekly Report'!$C$4,N(H5)<='Weekly Report'!$C$4+7))),COUNT(T$4:T4)+1,"")
A6: ACT-002 | B6: Assessment & Execution | C6: Reconcile EASM-discovered assets against CMDB extract | D6: Inventory Audit | E6: Visibility | F6: Me | G6: 46309 | H6: 46332 | I6: In Progress | K6: 46314 | L6: First pass done: ~18% of discovered hosts not in CMDB | O6: Yes | P6: =IF(OR(C6="",H6="",I6="Completed",I6="Cancelled"),"",IF(H6<TODAY(),"Overdue","")) | Q6: =IF(AND(C6<>"",I6<>"Cancelled",OR(AND(N(J6)>'Weekly Report'!$C$5,N(J6)<='Weekly Report'!$C$4),AND(N(K6)>'Weekly Report'!$C$5,N(K6)<='Weekly Report'!$C$4))),COUNT(Q$4:Q5)+1,"") -> 2 | R6: =IF(AND(C6<>"",I6="In Progress"),COUNT(R$4:R5)+1,"") -> 1 | S6: =IF(AND(C6<>"",I6<>"Completed",I6<>"Cancelled",OR(I6="Blocked",M6<>"")),COUNT(S$4:S5)+1,"") | T6: =IF(AND(C6<>"",I6<>"Completed",I6<>"Cancelled",OR(O6="Yes",AND(N(H6)>'Weekly Report'!$C$4,N(H6)<='Weekly Report'!$C$4+7))),COUNT(T$4:T5)+1,"") -> 1
A7: ACT-003 | B7: Assessment & Execution | C7: Review EASM operating procedure and asset ownership policy | D7: Document Review | E7: Governance | F7: Me | G7: 46314 | H7: 46322 | I7: Blocked | M7: Current version of the EASM procedure not yet shared by 1LoD | N7: Network Security (1LoD) | O7: Yes | P7: =IF(OR(C7="",H7="",I7="Completed",I7="Cancelled"),"",IF(H7<TODAY(),"Overdue","")) | Q7: =IF(AND(C7<>"",I7<>"Cancelled",OR(AND(N(J7)>'Weekly Report'!$C$5,N(J7)<='Weekly Report'!$C$4),AND(N(K7)>'Weekly Report'!$C$5,N(K7)<='Weekly Report'!$C$4))),COUNT(Q$4:Q6)+1,"") | R7: =IF(AND(C7<>"",I7="In Progress"),COUNT(R$4:R6)+1,"") | S7: =IF(AND(C7<>"",I7<>"Completed",I7<>"Cancelled",OR(I7="Blocked",M7<>"")),COUNT(S$4:S6)+1,"") -> 1 | T7: =IF(AND(C7<>"",I7<>"Completed",I7<>"Cancelled",OR(O7="Yes",AND(N(H7)>'Weekly Report'!$C$4,N(H7)<='Weekly Report'!$C$4+7))),COUNT(T$4:T6)+1,"") -> 2
A8: ACT-004 | P8: =IF(OR(C8="",H8="",I8="Completed",I8="Cancelled"),"",IF(H8<TODAY(),"Overdue","")) | Q8: =IF(AND(C8<>"",I8<>"Cancelled",OR(AND(N(J8)>'Weekly Report'!$C$5,N(J8)<='Weekly Report'!$C$4),AND(N(K8)>'Weekly Report'!$C$5,N(K8)<='Weekly Report'!$C$4))),COUNT(Q$4:Q7)+1,"") | R8: =IF(AND(C8<>"",I8="In Progress"),COUNT(R$4:R7)+1,"") | S8: =IF(AND(C8<>"",I8<>"Completed",I8<>"Cancelled",OR(I8="Blocked",M8<>"")),COUNT(S$4:S7)+1,"") | T8: =IF(AND(C8<>"",I8<>"Completed",I8<>"Cancelled",OR(O8="Yes",AND(N(H8)>'Weekly Report'!$C$4,N(H8)<='Weekly Report'!$C$4+7))),COUNT(T$4:T7)+1,"")
A9: ACT-005 | P9: =IF(OR(C9="",H9="",I9="Completed",I9="Cancelled"),"",IF(H9<TODAY(),"Overdue","")) | Q9: =IF(AND(C9<>"",I9<>"Cancelled",OR(AND(N(J9)>'Weekly Report'!$C$5,N(J9)<='Weekly Report'!$C$4),AND(N(K9)>'Weekly Report'!$C$5,N(K9)<='Weekly Report'!$C$4))),COUNT(Q$4:Q8)+1,"") | R9: =IF(AND(C9<>"",I9="In Progress"),COUNT(R$4:R8)+1,"") | S9: =IF(AND(C9<>"",I9<>"Completed",I9<>"Cancelled",OR(I9="Blocked",M9<>"")),COUNT(S$4:S8)+1,"") | T9: =IF(AND(C9<>"",I9<>"Completed",I9<>"Cancelled",OR(O9="Yes",AND(N(H9)>'Weekly Report'!$C$4,N(H9)<='Weekly Report'!$C$4+7))),COUNT(T$4:T8)+1,"")
A10: ACT-006 | P10: =IF(OR(C10="",H10="",I10="Completed",I10="Cancelled"),"",IF(H10<TODAY(),"Overdue","")) | Q10: =IF(AND(C10<>"",I10<>"Cancelled",OR(AND(N(J10)>'Weekly Report'!$C$5,N(J10)<='Weekly Report'!$C$4),AND(N(K10)>'Weekly Report'!$C$5,N(K10)<='Weekly Report'!$C$4))),COUNT(Q$4:Q9)+1,"") | R10: =IF(AND(C10<>"",I10="In Progress"),COUNT(R$4:R9)+1,"") | S10: =IF(AND(C10<>"",I10<>"Completed",I10<>"Cancelled",OR(I10="Blocked",M10<>"")),COUNT(S$4:S9)+1,"") | T10: =IF(AND(C10<>"",I10<>"Completed",I10<>"Cancelled",OR(O10="Yes",AND(N(H10)>'Weekly Report'!$C$4,N(H10)<='Weekly Report'!$C$4+7))),COUNT(T$4:T9)+1,"")
A11: ACT-007 | P11: =IF(OR(C11="",H11="",I11="Completed",I11="Cancelled"),"",IF(H11<TODAY(),"Overdue","")) | Q11: =IF(AND(C11<>"",I11<>"Cancelled",OR(AND(N(J11)>'Weekly Report'!$C$5,N(J11)<='Weekly Report'!$C$4),AND(N(K11)>'Weekly Report'!$C$5,N(K11)<='Weekly Report'!$C$4))),COUNT(Q$4:Q10)+1,"") | R11: =IF(AND(C11<>"",I11="In Progress"),COUNT(R$4:R10)+1,"") | S11: =IF(AND(C11<>"",I11<>"Completed",I11<>"Cancelled",OR(I11="Blocked",M11<>"")),COUNT(S$4:S10)+1,"") | T11: =IF(AND(C11<>"",I11<>"Completed",I11<>"Cancelled",OR(O11="Yes",AND(N(H11)>'Weekly Report'!$C$4,N(H11)<='Weekly Report'!$C$4+7))),COUNT(T$4:T10)+1,"")
A12: ACT-008 | P12: =IF(OR(C12="",H12="",I12="Completed",I12="Cancelled"),"",IF(H12<TODAY(),"Overdue","")) | Q12: =IF(AND(C12<>"",I12<>"Cancelled",OR(AND(N(J12)>'Weekly Report'!$C$5,N(J12)<='Weekly Report'!$C$4),AND(N(K12)>'Weekly Report'!$C$5,N(K12)<='Weekly Report'!$C$4))),COUNT(Q$4:Q11)+1,"") | R12: =IF(AND(C12<>"",I12="In Progress"),COUNT(R$4:R11)+1,"") | S12: =IF(AND(C12<>"",I12<>"Completed",I12<>"Cancelled",OR(I12="Blocked",M12<>"")),COUNT(S$4:S11)+1,"") | T12: =IF(AND(C12<>"",I12<>"Completed",I12<>"Cancelled",OR(O12="Yes",AND(N(H12)>'Weekly Report'!$C$4,N(H12)<='Weekly Report'!$C$4+7))),COUNT(T$4:T11)+1,"")
A13: ACT-009 | P13: =IF(OR(C13="",H13="",I13="Completed",I13="Cancelled"),"",IF(H13<TODAY(),"Overdue","")) | Q13: =IF(AND(C13<>"",I13<>"Cancelled",OR(AND(N(J13)>'Weekly Report'!$C$5,N(J13)<='Weekly Report'!$C$4),AND(N(K13)>'Weekly Report'!$C$5,N(K13)<='Weekly Report'!$C$4))),COUNT(Q$4:Q12)+1,"") | R13: =IF(AND(C13<>"",I13="In Progress"),COUNT(R$4:R12)+1,"") | S13: =IF(AND(C13<>"",I13<>"Completed",I13<>"Cancelled",OR(I13="Blocked",M13<>"")),COUNT(S$4:S12)+1,"") | T13: =IF(AND(C13<>"",I13<>"Completed",I13<>"Cancelled",OR(O13="Yes",AND(N(H13)>'Weekly Report'!$C$4,N(H13)<='Weekly Report'!$C$4+7))),COUNT(T$4:T12)+1,"")
A14: ACT-010 | P14: =IF(OR(C14="",H14="",I14="Completed",I14="Cancelled"),"",IF(H14<TODAY(),"Overdue","")) | Q14: =IF(AND(C14<>"",I14<>"Cancelled",OR(AND(N(J14)>'Weekly Report'!$C$5,N(J14)<='Weekly Report'!$C$4),AND(N(K14)>'Weekly Report'!$C$5,N(K14)<='Weekly Report'!$C$4))),COUNT(Q$4:Q13)+1,"") | R14: =IF(AND(C14<>"",I14="In Progress"),COUNT(R$4:R13)+1,"") | S14: =IF(AND(C14<>"",I14<>"Completed",I14<>"Cancelled",OR(I14="Blocked",M14<>"")),COUNT(S$4:S13)+1,"") | T14: =IF(AND(C14<>"",I14<>"Completed",I14<>"Cancelled",OR(O14="Yes",AND(N(H14)>'Weekly Report'!$C$4,N(H14)<='Weekly Report'!$C$4+7))),COUNT(T$4:T13)+1,"")
A15: ACT-011 | P15: =IF(OR(C15="",H15="",I15="Completed",I15="Cancelled"),"",IF(H15<TODAY(),"Overdue","")) | Q15: =IF(AND(C15<>"",I15<>"Cancelled",OR(AND(N(J15)>'Weekly Report'!$C$5,N(J15)<='Weekly Report'!$C$4),AND(N(K15)>'Weekly Report'!$C$5,N(K15)<='Weekly Report'!$C$4))),COUNT(Q$4:Q14)+1,"") | R15: =IF(AND(C15<>"",I15="In Progress"),COUNT(R$4:R14)+1,"") | S15: =IF(AND(C15<>"",I15<>"Completed",I15<>"Cancelled",OR(I15="Blocked",M15<>"")),COUNT(S$4:S14)+1,"") | T15: =IF(AND(C15<>"",I15<>"Completed",I15<>"Cancelled",OR(O15="Yes",AND(N(H15)>'Weekly Report'!$C$4,N(H15)<='Weekly Report'!$C$4+7))),COUNT(T$4:T14)+1,"")
A16: ACT-012 | P16: =IF(OR(C16="",H16="",I16="Completed",I16="Cancelled"),"",IF(H16<TODAY(),"Overdue","")) | Q16: =IF(AND(C16<>"",I16<>"Cancelled",OR(AND(N(J16)>'Weekly Report'!$C$5,N(J16)<='Weekly Report'!$C$4),AND(N(K16)>'Weekly Report'!$C$5,N(K16)<='Weekly Report'!$C$4))),COUNT(Q$4:Q15)+1,"") | R16: =IF(AND(C16<>"",I16="In Progress"),COUNT(R$4:R15)+1,"") | S16: =IF(AND(C16<>"",I16<>"Completed",I16<>"Cancelled",OR(I16="Blocked",M16<>"")),COUNT(S$4:S15)+1,"") | T16: =IF(AND(C16<>"",I16<>"Completed",I16<>"Cancelled",OR(O16="Yes",AND(N(H16)>'Weekly Report'!$C$4,N(H16)<='Weekly Report'!$C$4+7))),COUNT(T$4:T15)+1,"")
A17: ACT-013 | P17: =IF(OR(C17="",H17="",I17="Completed",I17="Cancelled"),"",IF(H17<TODAY(),"Overdue","")) | Q17: =IF(AND(C17<>"",I17<>"Cancelled",OR(AND(N(J17)>'Weekly Report'!$C$5,N(J17)<='Weekly Report'!$C$4),AND(N(K17)>'Weekly Report'!$C$5,N(K17)<='Weekly Report'!$C$4))),COUNT(Q$4:Q16)+1,"") | R17: =IF(AND(C17<>"",I17="In Progress"),COUNT(R$4:R16)+1,"") | S17: =IF(AND(C17<>"",I17<>"Completed",I17<>"Cancelled",OR(I17="Blocked",M17<>"")),COUNT(S$4:S16)+1,"") | T17: =IF(AND(C17<>"",I17<>"Completed",I17<>"Cancelled",OR(O17="Yes",AND(N(H17)>'Weekly Report'!$C$4,N(H17)<='Weekly Report'!$C$4+7))),COUNT(T$4:T16)+1,"")
A18: ACT-014 | P18: =IF(OR(C18="",H18="",I18="Completed",I18="Cancelled"),"",IF(H18<TODAY(),"Overdue","")) | Q18: =IF(AND(C18<>"",I18<>"Cancelled",OR(AND(N(J18)>'Weekly Report'!$C$5,N(J18)<='Weekly Report'!$C$4),AND(N(K18)>'Weekly Report'!$C$5,N(K18)<='Weekly Report'!$C$4))),COUNT(Q$4:Q17)+1,"") | R18: =IF(AND(C18<>"",I18="In Progress"),COUNT(R$4:R17)+1,"") | S18: =IF(AND(C18<>"",I18<>"Completed",I18<>"Cancelled",OR(I18="Blocked",M18<>"")),COUNT(S$4:S17)+1,"") | T18: =IF(AND(C18<>"",I18<>"Completed",I18<>"Cancelled",OR(O18="Yes",AND(N(H18)>'Weekly Report'!$C$4,N(H18)<='Weekly Report'!$C$4+7))),COUNT(T$4:T17)+1,"")
A19: ACT-015 | P19: =IF(OR(C19="",H19="",I19="Completed",I19="Cancelled"),"",IF(H19<TODAY(),"Overdue","")) | Q19: =IF(AND(C19<>"",I19<>"Cancelled",OR(AND(N(J19)>'Weekly Report'!$C$5,N(J19)<='Weekly Report'!$C$4),AND(N(K19)>'Weekly Report'!$C$5,N(K19)<='Weekly Report'!$C$4))),COUNT(Q$4:Q18)+1,"") | R19: =IF(AND(C19<>"",I19="In Progress"),COUNT(R$4:R18)+1,"") | S19: =IF(AND(C19<>"",I19<>"Completed",I19<>"Cancelled",OR(I19="Blocked",M19<>"")),COUNT(S$4:S18)+1,"") | T19: =IF(AND(C19<>"",I19<>"Completed",I19<>"Cancelled",OR(O19="Yes",AND(N(H19)>'Weekly Report'!$C$4,N(H19)<='Weekly Report'!$C$4+7))),COUNT(T$4:T18)+1,"")
... A204: ACT-200 | P204: =IF(OR(C204="",H204="",I204="Completed",I204="Cancelled"),"",IF(H204<TODAY(),"Overdue","")) | Q204: =IF(AND(C204<>"",I204<>"Cancelled",OR(AND(N(J204)>'Weekly Report'!$C$5,N(J204)<='Weekly Report'!$C$4),AND(N(K204)>'Weekly Report'!$C$5,N(K204)<='Weekly Report'!$C$4))),COUNT(Q$4:Q203)+1,"") | R204: =IF(AND(C204<>"",I204="In Progress"),COUNT(R$4:R203)+1,"") | S204: =IF(AND(C204<>"",I204<>"Completed",I204<>"Cancelled",OR(I204="Blocked",M204<>"")),COUNT(S$4:S203)+1,"") | T204: =IF(AND(C204<>"",I204<>"Completed",I204<>"Cancelled",OR(O204="Yes",AND(N(H204)>'Weekly Report'!$C$4,N(H204)<='Weekly Report'!$C$4+7))),COUNT(T$4:T203)+1,"")

Sheet Findings
A1: Findings
A2: Mission findings. 'This Period' flags new or materially changed findings for the weekly report.
A3: White = you type | Grey = automatic | Italic rows = examples (overwrite or delete)
A4: ID | B4: Date Identified | C4: Focus Area | D4: Method | E4: Finding (what & where) | F4: Risk / Impact | G4: Severity | H4: Remediation Owner | I4: Remediation Status | J4: Target Date | K4: Last Material Change | L4: What Changed / Remediation Update | M4: This Period | N4: Overdue? | O4: helper:rep
A5: FND-001 | B5: 46311 | C5: Visibility | D5: Inventory Audit | E5: ~18% of internet-facing hosts discovered by EASM are not recorded in the CMDB (mostly acquired entity B) | F5: Unmanaged assets outside patching and monitoring; incomplete ICT asset register | G5: High | H5: Network Security (1LoD) | I5: Open | J5: 46371 | L5: New – root cause analysis requested from 1LoD | M5: =IF(E5="","",IF(AND(N(B5)>'Weekly Report'!$C$5,N(B5)<='Weekly Report'!$C$4),"New",IF(AND(N(K5)>'Weekly Report'!$C$5,N(K5)<='Weekly Report'!$C$4),"Changed",""))) -> New | N5: =IF(OR(E5="",J5="",I5="Remediated",I5="Closed",I5="Risk Accepted"),"",IF(J5<TODAY(),"Overdue","")) | O5: =IF(M5<>"",COUNT(O$4:O4)+1,"") -> 1
A6: FND-002 | M6: =IF(E6="","",IF(AND(N(B6)>'Weekly Report'!$C$5,N(B6)<='Weekly Report'!$C$4),"New",IF(AND(N(K6)>'Weekly Report'!$C$5,N(K6)<='Weekly Report'!$C$4),"Changed",""))) | N6: =IF(OR(E6="",J6="",I6="Remediated",I6="Closed",I6="Risk Accepted"),"",IF(J6<TODAY(),"Overdue","")) | O6: =IF(M6<>"",COUNT(O$4:O5)+1,"")
A7: FND-003 | M7: =IF(E7="","",IF(AND(N(B7)>'Weekly Report'!$C$5,N(B7)<='Weekly Report'!$C$4),"New",IF(AND(N(K7)>'Weekly Report'!$C$5,N(K7)<='Weekly Report'!$C$4),"Changed",""))) | N7: =IF(OR(E7="",J7="",I7="Remediated",I7="Closed",I7="Risk Accepted"),"",IF(J7<TODAY(),"Overdue","")) | O7: =IF(M7<>"",COUNT(O$4:O6)+1,"")
A8: FND-004 | M8: =IF(E8="","",IF(AND(N(B8)>'Weekly Report'!$C$5,N(B8)<='Weekly Report'!$C$4),"New",IF(AND(N(K8)>'Weekly Report'!$C$5,N(K8)<='Weekly Report'!$C$4),"Changed",""))) | N8: =IF(OR(E8="",J8="",I8="Remediated",I8="Closed",I8="Risk Accepted"),"",IF(J8<TODAY(),"Overdue","")) | O8: =IF(M8<>"",COUNT(O$4:O7)+1,"")
A9: FND-005 | M9: =IF(E9="","",IF(AND(N(B9)>'Weekly Report'!$C$5,N(B9)<='Weekly Report'!$C$4),"New",IF(AND(N(K9)>'Weekly Report'!$C$5,N(K9)<='Weekly Report'!$C$4),"Changed",""))) | N9: =IF(OR(E9="",J9="",I9="Remediated",I9="Closed",I9="Risk Accepted"),"",IF(J9<TODAY(),"Overdue","")) | O9: =IF(M9<>"",COUNT(O$4:O8)+1,"")
A10: FND-006 | M10: =IF(E10="","",IF(AND(N(B10)>'Weekly Report'!$C$5,N(B10)<='Weekly Report'!$C$4),"New",IF(AND(N(K10)>'Weekly Report'!$C$5,N(K10)<='Weekly Report'!$C$4),"Changed",""))) | N10: =IF(OR(E10="",J10="",I10="Remediated",I10="Closed",I10="Risk Accepted"),"",IF(J10<TODAY(),"Overdue","")) | O10: =IF(M10<>"",COUNT(O$4:O9)+1,"")
A11: FND-007 | M11: =IF(E11="","",IF(AND(N(B11)>'Weekly Report'!$C$5,N(B11)<='Weekly Report'!$C$4),"New",IF(AND(N(K11)>'Weekly Report'!$C$5,N(K11)<='Weekly Report'!$C$4),"Changed",""))) | N11: =IF(OR(E11="",J11="",I11="Remediated",I11="Closed",I11="Risk Accepted"),"",IF(J11<TODAY(),"Overdue","")) | O11: =IF(M11<>"",COUNT(O$4:O10)+1,"")
A12: FND-008 | M12: =IF(E12="","",IF(AND(N(B12)>'Weekly Report'!$C$5,N(B12)<='Weekly Report'!$C$4),"New",IF(AND(N(K12)>'Weekly Report'!$C$5,N(K12)<='Weekly Report'!$C$4),"Changed",""))) | N12: =IF(OR(E12="",J12="",I12="Remediated",I12="Closed",I12="Risk Accepted"),"",IF(J12<TODAY(),"Overdue","")) | O12: =IF(M12<>"",COUNT(O$4:O11)+1,"")
A13: FND-009 | M13: =IF(E13="","",IF(AND(N(B13)>'Weekly Report'!$C$5,N(B13)<='Weekly Report'!$C$4),"New",IF(AND(N(K13)>'Weekly Report'!$C$5,N(K13)<='Weekly Report'!$C$4),"Changed",""))) | N13: =IF(OR(E13="",J13="",I13="Remediated",I13="Closed",I13="Risk Accepted"),"",IF(J13<TODAY(),"Overdue","")) | O13: =IF(M13<>"",COUNT(O$4:O12)+1,"")
A14: FND-010 | M14: =IF(E14="","",IF(AND(N(B14)>'Weekly Report'!$C$5,N(B14)<='Weekly Report'!$C$4),"New",IF(AND(N(K14)>'Weekly Report'!$C$5,N(K14)<='Weekly Report'!$C$4),"Changed",""))) | N14: =IF(OR(E14="",J14="",I14="Remediated",I14="Closed",I14="Risk Accepted"),"",IF(J14<TODAY(),"Overdue","")) | O14: =IF(M14<>"",COUNT(O$4:O13)+1,"")
A15: FND-011 | M15: =IF(E15="","",IF(AND(N(B15)>'Weekly Report'!$C$5,N(B15)<='Weekly Report'!$C$4),"New",IF(AND(N(K15)>'Weekly Report'!$C$5,N(K15)<='Weekly Report'!$C$4),"Changed",""))) | N15: =IF(OR(E15="",J15="",I15="Remediated",I15="Closed",I15="Risk Accepted"),"",IF(J15<TODAY(),"Overdue","")) | O15: =IF(M15<>"",COUNT(O$4:O14)+1,"")
A16: FND-012 | M16: =IF(E16="","",IF(AND(N(B16)>'Weekly Report'!$C$5,N(B16)<='Weekly Report'!$C$4),"New",IF(AND(N(K16)>'Weekly Report'!$C$5,N(K16)<='Weekly Report'!$C$4),"Changed",""))) | N16: =IF(OR(E16="",J16="",I16="Remediated",I16="Closed",I16="Risk Accepted"),"",IF(J16<TODAY(),"Overdue","")) | O16: =IF(M16<>"",COUNT(O$4:O15)+1,"")
A17: FND-013 | M17: =IF(E17="","",IF(AND(N(B17)>'Weekly Report'!$C$5,N(B17)<='Weekly Report'!$C$4),"New",IF(AND(N(K17)>'Weekly Report'!$C$5,N(K17)<='Weekly Report'!$C$4),"Changed",""))) | N17: =IF(OR(E17="",J17="",I17="Remediated",I17="Closed",I17="Risk Accepted"),"",IF(J17<TODAY(),"Overdue","")) | O17: =IF(M17<>"",COUNT(O$4:O16)+1,"")
... A204: FND-200 | M204: =IF(E204="","",IF(AND(N(B204)>'Weekly Report'!$C$5,N(B204)<='Weekly Report'!$C$4),"New",IF(AND(N(K204)>'Weekly Report'!$C$5,N(K204)<='Weekly Report'!$C$4),"Changed",""))) | N204: =IF(OR(E204="",J204="",I204="Remediated",I204="Closed",I204="Risk Accepted"),"",IF(J204<TODAY(),"Overdue","")) | O204: =IF(M204<>"",COUNT(O$4:O203)+1,"")

Sheet Escalations
A1: Escalations & Decisions
A2: Items that need an escalation or a decision. Open items appear in the weekly report.
A3: White = you type | Grey = automatic | Italic rows = examples (overwrite or delete)
A4: ID | B4: Date Raised | C4: Type | D4: Issue / Decision Required | E4: Impact if Unresolved | F4: Options / Recommendation | G4: Escalate To / Decision Maker | H4: Needed By | I4: Status | J4: Resolution Date | K4: Outcome | L4: helper:open
A5: ESC-001 | B5: 46314 | C5: Decision Needed | D5: Extend mission scope to the 3 acquired entities' domains and IP ranges | E5: Material part of the external attack surface would stay unassessed | F5: Approve extension; timeline +2 weeks for phase 2 | G5: Mission Sponsor | H5: 46322 | I5: Open | L5: =IF(AND(D5<>"",I5="Open"),COUNT(L$4:L4)+1,"") -> 1
A6: ESC-002 | L6: =IF(AND(D6<>"",I6="Open"),COUNT(L$4:L5)+1,"")
A7: ESC-003 | L7: =IF(AND(D7<>"",I7="Open"),COUNT(L$4:L6)+1,"")
A8: ESC-004 | L8: =IF(AND(D8<>"",I8="Open"),COUNT(L$4:L7)+1,"")
A9: ESC-005 | L9: =IF(AND(D9<>"",I9="Open"),COUNT(L$4:L8)+1,"")
A10: ESC-006 | L10: =IF(AND(D10<>"",I10="Open"),COUNT(L$4:L9)+1,"")
A11: ESC-007 | L11: =IF(AND(D11<>"",I11="Open"),COUNT(L$4:L10)+1,"")
A12: ESC-008 | L12: =IF(AND(D12<>"",I12="Open"),COUNT(L$4:L11)+1,"")
A13: ESC-009 | L13: =IF(AND(D13<>"",I13="Open"),COUNT(L$4:L12)+1,"")
A14: ESC-010 | L14: =IF(AND(D14<>"",I14="Open"),COUNT(L$4:L13)+1,"")
A15: ESC-011 | L15: =IF(AND(D15<>"",I15="Open"),COUNT(L$4:L14)+1,"")
A16: ESC-012 | L16: =IF(AND(D16<>"",I16="Open"),COUNT(L$4:L15)+1,"")
A17: ESC-013 | L17: =IF(AND(D17<>"",I17="Open"),COUNT(L$4:L16)+1,"")
... A204: ESC-200 | L204: =IF(AND(D204<>"",I204="Open"),COUNT(L$4:L203)+1,"")

Sheet Meetings & Emails
A1: Meetings & Emails
A2: Record of meetings, emails and calls under the mission.
A3: White = you type | Grey = automatic | Italic rows = examples (overwrite or delete)
A4: ID | B4: Date | C4: Type | D4: Subject | E4: With (people / function) | F4: Key Points / Outcome | G4: Actions Created (IDs) | H4: Notes
A5: LOG-001 | B5: 46310 | C5: Meeting | D5: EASM mission kick-off | E5: CISO Office; Network Security; Group Architecture | F5: Scope and data requests agreed; CMDB extract to be shared by 1LoD | G5: ACT-001; ACT-002
A6: LOG-002
A7: LOG-003
A8: LOG-004
A9: LOG-005
A10: LOG-006
A11: LOG-007
A12: LOG-008
A13: LOG-009
A14: LOG-010
A15: LOG-011
A16: LOG-012
A17: LOG-013
... A204: LOG-200

Sheet How To Use
A1: How To Use
A3: WEEKLY ROUTINE (≈10 min before the meeting)
A4: 1. Actions | B4: Update Status, Last Updated date and Progress Note for anything that moved. Fill Blocker / Waiting On where relevant. Set 'Plan for Next Week' = Yes for next week's work.
A5: 2. Findings | B5: Add new findings. For existing ones, set 'Last Material Change' and describe the change and the remediation status.
A6: 3. Escalations | B6: Add anything needing escalation or a decision. Set Status = Resolved once closed.
A7: 4. Weekly Status | B7: Add one row: meeting date, overall RAG and one sentence explaining why. Check it against the 'Suggested RAG' on the report.
A8: 5. Timeline | B8: Update phase status and actual dates when a phase starts or ends.
A9: 6. Weekly Report | B9: Check the meeting date (defaults to today). All 8 sections fill in automatically. Print (1 page wide) or copy into email or slides.
A10: HOW ITEMS REACH THE REPORT
A11: Progress since last week | B11: Actions completed, or with 'Last Updated', after the previous meeting and up to this meeting.
A12: Current work | B12: Actions with Status = In Progress.
A13: Findings | B13: Findings identified, or materially changed, in the reporting period.
A14: Blockers & dependencies | B14: Open actions with Status = Blocked or with a Blocker / Dependency entered.
A15: Plan for next week | B15: Open actions flagged 'Plan for Next Week' = Yes, or due within 7 days after the meeting.
A16: Escalations & decisions | B16: Escalations with Status = Open.
A17: MISSION STRUCTURE
A18: Phases | B18: Kick-off & Alignment → Assessment & Execution → Reporting & Conclusion
A19: Methods | B19: Document Review · Stakeholder Engagement · Inventory Audit · Completeness Validation
A20: Focus areas | B20: Visibility · Governance · Integration · Sustainability (coverage matrix on the Timeline tab)
A21: NOTES
A22: Colours | B22: Emerald = headers. White = input. Grey = automatic, do not overwrite. Green / amber / red = status.
A23: Examples | B23: Italic rows are examples. Overwrite or delete them before first use.
A24: Capacity | B24: 200 rows per log. Report shows up to 8 items per section; the section header shows the total.

Sheet Lists
A1: Dropdown values (edit here if needed)
A3: Phase | B3: Method | C3: Focus | D3: ActStatus | E3: PhaseStatus | F3: RAG | G3: Severity | H3: RemStatus | I3: EscType | J3: EscStatus | K3: LogType | L3: YesNo
A4: Kick-off & Alignment | B4: Document Review | C4: Visibility | D4: Not Started | E4: Not Started | F4: Green | G4: Critical | H4: Open | I4: Escalation | J4: Open | K4: Meeting | L4: Yes
A5: Assessment & Execution | B5: Stakeholder Engagement | C5: Governance | D5: In Progress | E5: In Progress | F5: Amber | G5: High | H5: In Progress | I5: Decision Needed | J5: Resolved | K5: Email | L5: No
A6: Reporting & Conclusion | B6: Inventory Audit | C6: Integration | D6: Blocked | E6: Delayed | F6: Red | G6: Medium | H6: Remediated | K6: Call
B7: Completeness Validation | C7: Sustainability | D7: Completed | E7: Completed | G7: Low | H7: Risk Accepted
B8: N/A (Project Mgmt) | C8: Cross-cutting | D8: Cancelled | H8: Closed
